Workbook

Sheet PB 
D1: Vessel name
B2: Vessel Name
B3: P O R T A G E B I L L - MONTH OF | J3: 46023
B4: E A R N I N G S | Q4: DEDUCTIONS
B5: SR. No | C5: NAME | D5: RANK | E5: FM | F5: TO | G5: DAYS | H5: BASIC | I5: FIXED OT | J5: LEAVE WAGES | K5: OTHER ALLOWANCES | L5: Travel Wages | M5: HRA | N5: JOINING EXPENSES | O5: ONBOARD ALLOWANCE / SHORT MANNING | P5: TOTAL EARNINGS | Q5: CASH DRAWN ON BOARD | R5: HOME ALLOMENT | S5: BOND | T5: OTHER DEDUCTION | U5: TOTAL DEDUCTION | V5: BROUGHT FORWARD | W5: FINAL BALANCE | X5: SIGN
B7: 1 | D7: Master | E7: 28 | F7: 31 | G7: =IF(E7=1,IF(F7>=29,(F7-E7)+1),(F7-E7)+1) -> 4 | H7: =2267*G7/30 -> 302.26667 | I7: =1417*G7/30 -> 188.93333 | J7: =188.94*G7/30 -> 25.192 | K7: =10127.06*G7/30 -> 1350.2747 | L7: =2267/30*1 -> 75.566667 | M7: 0 | N7: 75.24 | O7: 0 | P7: =SUM(H7:O7) -> 2017.4733 | Q7: 0 | R7: 7000 | S7: 0 | U7: =SUM(Q7:T7) -> 7000 | V7: 0 | W7: =P7+V7-U7 -> -4982.5267
B8: 2 | D8: Ch.Officer | E8: 1 | F8: 31 | G8: =IF(E8=1,IF(F8>=29,30,(F8-E8)+1),(F8-E8)+1) -> 30 | H8: =1464*G8/30 -> 1464 | I8: =915*G8/30 -> 915 | J8: =192.35*G8/30 -> 192.35 | K8: =8428.65*G8/30 -> 8428.65 | L8: 0 | M8: 0 | N8: 0 | O8: 0 | P8: =SUM(H8:O8) -> 11000 | Q8: 0 | R8: =P8+V8-(Q8+S8+T8) -> 11000 | S8: 0 | T8: 0 | U8: =SUM(Q8:T8) -> 11000 | V8: 0 | W8: =P8+V8-U8 -> 0
B9: 3 | D9: Adtnl Ch.Officer | E9: 1 | F9: 31 | G9: =IF(E9=1,IF(F9>=29,30,(F9-E9)+1),(F9-E9)+1) -> 30 | H9: =1464*G9/30 -> 1464 | I9: =915*G9/30 -> 915 | J9: =121.98*G9/30 -> 121.98 | K9: =2549.02*G9/30 -> 2549.02 | L9: 0 | M9: 0 | N9: 0 | O9: 0 | P9: =SUM(H9:O9) -> 5050 | Q9: 0 | R9: =P9+V9-(Q9+S9+T9) -> 5050 | S9: 0 | T9: 0 | U9: =SUM(Q9:T9) -> 5050 | V9: 0 | W9: =P9+V9-U9 -> 0
B10: 4 | D10: 2nd Officer | E10: 1 | F10: 31 | G10: =IF(E10=1,IF(F10>=29,30,(F10-E10)+1),(F10-E10)+1) -> 30 | H10: =1172*G10/30 -> 1172 | I10: =733*G10/30 -> 733 | J10: =97.7*G10/30 -> 97.7 | K10: =2197.3*G10/30 -> 2197.3 | L10: 0 | M10: 0 | N10: 0 | O10: 0 | P10: =SUM(H10:O10) -> 4200 | Q10: 0 | R10: =P10+V10-(Q10+S10+T10) -> 4193.08 | S10: 6.92 | T10: 0 | U10: =SUM(Q10:T10) -> 4200 | V10: 0 | W10: =P10+V10-U10 -> 0
B11: 5 | D11: Deck Cadet | E11: 28 | F11: 31 | G11: =IF(E11=1,IF(F11>=29,(F11-E11)+1),(F11-E11)+1) -> 4 | H11: =199/30*G11 -> 26.533333 | I11: =125/30*G11 -> 16.666667 | J11: =26/30*G11 -> 3.4666667 | K11: 0 | L11: =199/30*1 -> 6.6333333 | M11: 0 | N11: 32.73 | O11: 0 | P11: =SUM(H11:O11) -> 86.03 | Q11: 0 | R11: =P11+V11-(Q11+S11+T11) -> 86.03 | S11: 0 | T11: 0 | U11: =SUM(Q11:T11) -> 86.03 | V11: 0 | W11: =P11+V11-U11 -> 0
B12: 6 | D12: Ch.Engineer | E12: 28 | F12: 31 | G12: =IF(E12=1,IF(F12>=29,(F12-E12)+1),(F12-E12)+1) -> 4 | H12: =2061*G12/30 -> 274.8 | I12: =1288*G12/30 -> 171.73333 | J12: =297.01*G12/30 -> 39.601333 | K12: =11553.99*G12/30 -> 1540.532 | L12: =2061/30*1 -> 68.7 | M12: 0 | N12: 67.65 | O12: 0 | P12: =SUM(H12:O12) -> 2163.0167 | Q12: 0 | R12: =P12+V12-(Q12+S12+T12) -> 2163.0167 | S12: 0 | T12: 0 | U12: =SUM(Q12:T12) -> 2163.0167 | V12: 0 | W12: =P12+V12-U12 -> 0
B13: 7 | D13: 2nd Engineer | E13: 1 | F13: 31 | G13: =IF(E13=1,IF(F13>=29,30,(F13-E13)+1),(F13-E13)+1) -> 30 | H13: =1464*G13/30 -> 1464 | I13: =915*G13/30 -> 915 | J13: =192.35*G13/30 -> 192.35 | K13: =9928.65*G13/30 -> 9928.65 | L13: 0 | M13: 0 | N13: 0 | O13: 0 | P13: =SUM(H13:O13) -> 12500 | Q13: 0 | R13: =P13+V13-(Q13+S13+T13) -> 12500 | S13: 0 | T13: 0 | U13: =SUM(Q13:T13) -> 12500 | V13: 0 | W13: =P13+V13-U13 -> 0
B14: 8 | D14: 3rd.Engineer | E14: 29 | F14: 31 | G14: =IF(E14=1,IF(F14>=29,(F14-E14)+1),(F14-E14)+1) -> 3 | H14: =1172*G14/30 -> 117.2 | I14: =733*G14/30 -> 73.3 | J14: =97.7*G14/30 -> 9.77 | K14: =997.3*G14/30 -> 99.73 | L14: 0 | M14: 0 | N14: 0 | O14: 0 | P14: =SUM(H14:O14) -> 300 | Q14: 0 | R14: =P14+V14-(Q14+S14+T14) -> 300 | S14: 0 | T14: 0 | U14: =SUM(Q14:T14) -> 300 | V14: 0 | W14: =P14+V14-U14 -> 0
B15: 9 | D15: 4th Engineer | E15: 28 | F15: 31 | G15: =IF(E15=1,IF(F15>=29,30,(F15-E15)+1),(F15-E15)+1) -> 4 | H15: =854*G15/30 -> 113.86667 | I15: =534*G15/30 -> 71.2 | J15: =71.17*G15/30 -> 9.4893333 | K15: =1140.83*G15/30 -> 152.11067 | L15: =854/30*1 -> 28.466667 | M15: 0 | N15: 0 | O15: 0 | P15: =SUM(H15:O15) -> 375.13333 | Q15: 0 | R15: =P15+V15-(Q15+S15+T15) -> 375.13333 | S15: 0 | T15: 0 | U15: =SUM(Q15:T15) -> 375.13333 | V15: 0 | W15: =P15+V15-U15 -> 0
B16: 10 | D16: TME | E16: 1 | F16: 31 | G16: =IF(E16=1,IF(F16>=29,30,(F16-E16)+1),(F16-E16)+1) -> 30 | H16: =199/30*G16 -> 199 | I16: =125/30*G16 -> 125 | J16: =26/30*G16 -> 26 | K16: 0 | L16: 0 | M16: 0 | N16: 0 | O16: 0 | P16: =SUM(H16:O16) -> 350 | Q16: 0 | R16: =P16+V16-(Q16+S16+T16) -> 350 | S16: 0 | T16: 0 | U16: =SUM(Q16:T16) -> 350 | V16: 0 | W16: =P16+V16-U16 -> 0
B17: 11 | D17: Eletrical Officer | E17: 1 | F17: 31 | G17: =IF(E17=1,IF(F17>=29,30,(F17-E17)+1),(F17-E17)+1) -> 30 | H17: =1172*G17/30 -> 1172 | I17: =733*G17/30 -> 733 | J17: =97.7*G17/30 -> 97.7 | K17: =4997.3*G17/30 -> 4997.3 | M17: 0 | N17: 0 | O17: 0 | P17: =SUM(H17:O17) -> 7000 | Q17: 500 | R17: =P17+V17-(Q17+S17+T17) -> 6472.32 | S17: 27.68 | T17: 0 | U17: =SUM(Q17:T17) -> 7000 | V17: 0 | W17: =P17+V17-U17 -> 0
C18: TOTAL (A) | H18: =SUM(H7:H17) -> 7769.6667 | I18: =SUM(I7:I17) -> 4857.8333 | J18: =SUM(J7:J17) -> 815.59933 | K18: =SUM(K7:K17) -> 31243.567 | L18: =SUM(L7:L17) -> 179.36667 | M18: =SUM(M7:M17) -> 0 | N18: =SUM(N7:N17) -> 175.62 | O18: =SUM(O7:O17) -> 0 | ... W18: =SUM(W7:W17) -> -4982.5267
B19: 12 | D19: Pumpman | E19: 1 | F19: 31 | G19: =IF(E19=1,IF(F19>=29,30,(F19-E19)+1),(F19-E19)+1) -> 30 | H19: =752*G19/30 -> 752 | I19: =470*G19/30 -> 470 | J19: =62.65*G19/30 -> 62.65 | K19: =1515.35*G19/30 -> 1515.35 | L19: 0 | M19: 0 | N19: 0 | O19: 0 | P19: =SUM(H19:O19) -> 2800 | Q19: 0 | R19: =P19+V19-(Q19+S19+T19) -> 2800 | S19: 0 | T19: 0 | U19: =SUM(Q19:T19) -> 2800 | V19: 0 | W19: =P19+V19-U19 -> 0
B20: 13 | D20: Bosun | E20: 1 | F20: 31 | G20: =IF(E20=1,IF(F20>=29,30,(F20-E20)+1),(F20-E20)+1) -> 30 | H20: =752*G20/30 -> 752 | I20: =470*G20/30 -> 470 | J20: =62.65*G20/30 -> 62.65 | K20: =715.35*G20/30 -> 715.35 | L20: 0 | M20: 0 | N20: 0 | O20: 16.6 | P20: =SUM(H20:O20) -> 2016.6 | Q20: 0 | R20: =P20+V20-(Q20+S20+T20) -> 2016.6 | S20: 0 | T20: 0 | U20: =SUM(Q20:T20) -> 2016.6 | V20: 0 | W20: =P20+V20-U20 -> 0
B21: 14 | D21: AB 1 | E21: 1 | F21: 31 | G21: =IF(E21=1,IF(F21>=29,30,(F21-E21)+1),(F21-E21)+1) -> 30 | H21: =673*G21/30 -> 673 | I21: =421*G21/30 -> 421 | J21: =88.44*G21/30 -> 88.44 | K21: =367.56*G21/30 -> 367.56 | L21: 0 | M21: 0 | N21: 0 | O21: 16.6 | P21: =SUM(H21:O21) -> 1566.6 | Q21: 0 | R21: =P21+V21-(Q21+S21+T21) -> 1566.6 | S21: 0 | T21: 0 | U21: =SUM(Q21:T21) -> 1566.6 | V21: 0 | W21: =P21+V21-U21 -> 0
B22: 15 | D22: AB 2 | E22: 1 | F22: 31 | G22: =IF(E22=1,IF(F22>=29,30,(F22-E22)+1),(F22-E22)+1) -> 30 | H22: =673*G22/30 -> 673 | I22: =421*G22/30 -> 421 | J22: =88.44*G22/30 -> 88.44 | K22: =267.56*G22/30 -> 267.56 | L22: 0 | M22: 0 | N22: 0 | O22: 16.6 | P22: =SUM(H22:O22) -> 1466.6 | Q22: 0 | R22: =P22+V22-(Q22+S22+T22) -> 1466.6 | S22: 0 | T22: 0 | U22: =SUM(Q22:T22) -> 1466.6 | V22: 0 | W22: =P22+V22-U22 -> 0
B23: 16 | D23: AB 3 | E23: 1 | F23: 31 | G23: =IF(E23=1,IF(F23>=29,30,(F23-E23)+1),(F23-E23)+1) -> 30 | H23: =673*G23/30 -> 673 | I23: =421*G23/30 -> 421 | J23: =88.44*G23/30 -> 88.44 | K23: =217.56*G23/30 -> 217.56 | L23: 0 | M23: 0 | N23: 0 | O23: 16.6 | P23: =SUM(H23:O23) -> 1416.6 | Q23: 100 | R23: =P23+V23-(Q23+S23+T23) -> 1316.6 | S23: 0 | T23: 0 | U23: =SUM(Q23:T23) -> 1416.6 | V23: 0 | W23: =P23+V23-U23 -> 0
B24: 17 | D24: OS 1 | E24: 1 | F24: 31 | G24: =IF(E24=1,IF(F24>=29,30,(F24-E24)+1),(F24-E24)+1) -> 30 | H24: =285*G24/30 -> 285 | I24: =178*G24/30 -> 178 | J24: =24*G24/30 -> 24 | K24: =14*G24/30 -> 14 | L24: 0 | M24: 0 | N24: 0 | O24: 16.8 | P24: =SUM(H24:O24) -> 517.8 | Q24: 0 | R24: =P24+V24-(Q24+S24+T24) -> 517.8 | S24: 0 | T24: 0 | U24: =SUM(Q24:T24) -> 517.8 | V24: 0 | W24: =P24+V24-U24 -> 0
B25: 18 | D25: OS 2 | E25: 1 | F25: 31 | G25: =IF(E25=1,IF(F25>=29,30,(F25-E25)+1),(F25-E25)+1) -> 30 | H25: =285*G25/30 -> 285 | I25: =178*G25/30 -> 178 | J25: =38*G25/30 -> 38 | K25: =49*G25/30 -> 49 | L25: 0 | M25: 0 | N25: 0 | O25: 16.8 | P25: =SUM(H25:O25) -> 566.8 | Q25: 0 | R25: =P25+V25-(Q25+S25+T25) -> 566.8 | S25: 0 | T25: 0 | U25: =SUM(Q25:T25) -> 566.8 | V25: 0 | W25: =P25+V25-U25 -> 0
B26: 19 | D26: Oiler 1 | E26: 1 | F26: 31 | G26: =IF(E26=1,IF(F26>=29,30,(F26-E26)+1),(F26-E26)+1) -> 30 | H26: =673*G26/30 -> 673 | I26: =421*G26/30 -> 421 | J26: =88.44*G26/30 -> 88.44 | K26: =267.56*G26/30 -> 267.56 | L26: 0 | M26: 0 | N26: 0 | O26: 37.5 | P26: =SUM(H26:O26) -> 1487.5 | Q26: 0 | R26: =P26+V26-(Q26+S26+T26) -> 1480.58 | S26: 6.92 | T26: 0 | U26: =SUM(Q26:T26) -> 1487.5 | V26: 0 | W26: =P26+V26-U26 -> 0
B27: 20 | D27: Oiler 2 | E27: 1 | F27: 31 | G27: =IF(E27=1,IF(F27>=29,30,(F27-E27)+1),(F27-E27)+1) -> 30 | H27: =673*G27/30 -> 673 | I27: =421*G27/30 -> 421 | J27: =88.44*G27/30 -> 88.44 | K27: =217.56*G27/30 -> 217.56 | L27: 0 | M27: 0 | N27: 0 | O27: 37.5 | P27: =SUM(H27:O27) -> 1437.5 | Q27: 200 | R27: =P27+V27-(Q27+S27+T27) -> 1237.5 | S27: 0 | T27: 0 | U27: =SUM(Q27:T27) -> 1437.5 | V27: 0 | W27: =P27+V27-U27 -> 0
B28: 21 | D28: Oiler 3 | E28: 28 | F28: 31 | G28: =IF(E28=1,IF(F28>=29,(F28-E28)+1),(F28-E28)+1) -> 4 | H28: =673*G28/30 -> 89.733333 | I28: =421*G28/30 -> 56.133333 | J28: =56.08*G28/30 -> 7.4773333 | K28: =399.92*G28/30 -> 53.322667 | L28: =673/30*1 -> 22.433333 | M28: 0 | N28: 92.78 | O28: 0 | P28: =SUM(H28:O28) -> 321.88 | Q28: 0 | R28: =P28+V28-(Q28+S28+T28) -> 321.88 | S28: 0 | T28: 0 | U28: =SUM(Q28:T28) -> 321.88 | V28: 0 | W28: =P28+V28-U28 -> 0
B29: 22 | D29: Fitter | E29: 28 | F29: 31 | G29: =IF(E29=1,IF(F29>=29,(F29-E29)+1),(F29-E29)+1) -> 4 | H29: =752*G29/30 -> 100.26667 | I29: =470*G29/30 -> 62.666667 | J29: =62.65*G29/30 -> 8.3533333 | K29: =315.35*G29/30 -> 42.046667 | L29: =752/30*1 -> 25.066667 | M29: 0 | N29: 0 | O29: 0 | P29: =SUM(H29:O29) -> 238.4 | Q29: 0 | R29: =P29+V29-(Q29+S29+T29) -> 238.4 | S29: 0 | T29: 0 | U29: =SUM(Q29:T29) -> 238.4 | V29: 0 | W29: =P29+V29-U29 -> 0
B30: 23 | D30: Chief Cook | E30: 1 | F30: 31 | G30: =IF(E30=1,IF(F30>=29,30,(F30-E30)+1),(F30-E30)+1) -> 30 | H30: =752*G30/30 -> 752 | I30: =470*G30/30 -> 470 | J30: =98.79*G30/30 -> 98.79 | K30: =279.21*G30/30 -> 279.21 | L30: 0 | M30: 0 | N30: 0 | O30: 0 | P30: =SUM(H30:O30) -> 1600 | Q30: 100 | R30: =P30+V30-(Q30+S30+T30) -> 1500 | S30: 0 | T30: 0 | U30: =SUM(Q30:T30) -> 1600 | V30: 0 | W30: =P30+V30-U30 -> 0
B31: 24 | D31: GS | E31: 1 | F31: 31 | G31: =IF(E31=1,IF(F31>=29,30,(F31-E31)+1),(F31-E31)+1) -> 30 | H31: =199*G31/30 -> 199 | I31: =125*G31/30 -> 125 | J31: =26*G31/30 -> 26 | K31: =100*G31/30 -> 100 | L31: 0 | M31: 0 | N31: 0 | O31: 0 | P31: =SUM(H31:O31) -> 450 | Q31: 0 | R31: =P31+V31-(Q31+S31+T31) -> 450 | S31: 0 | T31: 0 | U31: =SUM(Q31:T31) -> 450 | V31: 0 | W31: =P31+V31-U31 -> 0
C32: TOTAL (B) | H32: =SUM(H19:H31) -> 6580 | I32: =SUM(I19:I31) -> 4114.8 | J32: =SUM(J19:J31) -> 770.12067 | K32: =SUM(K19:K31) -> 4106.0793 | L32: =SUM(L19:L31) -> 47.5 | M32: =SUM(M19:M31) -> 0 | N32: =SUM(N19:N31) -> 92.78 | O32: =SUM(O19:O31) -> 175 | ... W32: =SUM(W19:W31) -> 0
B33: OFF SIGNERS DURING THE MONTH | E33: 0
B34: 1 | D34: Master | E34: 1 | F34: 29 | G34: =IF(E34=1,IF(F34>=29,(F34-E34)+1),(F34-E34)+1) -> 29 | H34: =2267*G34/30 -> 2191.4333 | I34: =1417*G34/30 -> 1369.7667 | J34: =188.94*G34/30 -> 182.642 | K34: =12127.06*G34/30 -> 11722.825 | L34: =2267/30*1 -> 75.566667 | M34: 0 | N34: 92.78 | O34: 0 | P34: =SUM(H34:O34) -> 15635.013 | Q34: 253 | R34: =P34+V34-(Q34+S34+T34) -> 15382.013 | S34: 0 | T34: 0 | U34: =SUM(Q34:T34) -> 15635.013 | V34: 0 | W34: =P34+V34-U34 -> 0 | X34: SIGNED OFF
B35: 2 | D35: Deck Cadet | E35: 1 | F35: 29 | G35: =IF(E35=1,IF(F35>=29,(F35-E35)+1),(F35-E35)+1) -> 29 | H35: =199/30*G35 -> 192.36667 | I35: =125/30*G35 -> 120.83333 | J35: =26/30*G35 -> 25.133333 | K35: 0 | L35: =199/30*1 -> 6.6333333 | M35: 0 | N35: 0 | O35: 0 | P35: =SUM(H35:O35) -> 344.96667 | Q35: 0 | R35: =P35+V35-(Q35+S35+T35) -> 344.96667 | S35: 0 | T35: 0 | U35: =SUM(Q35:T35) -> 344.96667 | V35: 0 | W35: =P35+V35-U35 -> 0 | X35: SIGNED OFF
B36: 3 | D36: Ch.Engineer | E36: 1 | F36: 29 | G36: =IF(E36=1,IF(F36>=29,(F36-E36)+1),(F36-E36)+1) -> 29 | H36: =2061*G36/30 -> 1992.3 | I36: =1288*G36/30 -> 1245.0667 | J36: =297.01*G36/30 -> 287.10967 | K36: =11053.99*G36/30 -> 10685.524 | L36: =2061/30*1 -> 68.7 | M36: 0 | N36: 0 | O36: 0 | P36: =SUM(H36:O36) -> 14278.7 | Q36: 0 | R36: 0 | S36: 0 | T36: 0 | U36: =SUM(Q36:T36) -> 0 | V36: 32418.96 | W36: =P36+V36-U36 -> 46697.66 | X36: SIGNED OFF
B37: 4 | D37: 3rd.Engineer | E37: 1 | F37: 29 | G37: =IF(E37=1,IF(F37>=29,(F37-E37)+1),(F37-E37)+1) -> 29 | H37: =1172*G37/30 -> 1132.9333 | I37: =733*G37/30 -> 708.56667 | J37: =97.7*G37/30 -> 94.443333 | K37: =2797.3*G37/30 -> 2704.0567 | L37: =1172/30*1 -> 39.066667 | M37: 0 | N37: 0 | O37: 0 | P37: =SUM(H37:O37) -> 4679.0667 | Q37: 400 | R37: =P37+V37-(Q37+S37+T37) -> 4263.9267 | S37: 15.14 | T37: 0 | U37: =SUM(Q37:T37) -> 4679.0667 | V37: 0 | W37: =P37+V37-U37 -> 0 | X37: SIGNED OFF
B38: 5 | D38: Oiler 3 | E38: 1 | F38: 29 | G38: =IF(E38=1,IF(F38>=29,(F38-E38)+1),(F38-E38)+1) -> 29 | H38: =673*G38/30 -> 650.56667 | I38: =421*G38/30 -> 406.96667 | J38: =56.08*G38/30 -> 54.210667 | K38: =149.92*G38/30 -> 144.92267 | L38: =673/30*1 -> 22.433333 | M38: 0 | N38: 0 | O38: 37.5 | P38: =SUM(H38:O38) -> 1316.6 | Q38: 400 | R38: =P38+V38-(Q38+S38+T38) -> 916.6 | S38: 0 | T38: 0 | U38: =SUM(Q38:T38) -> 1316.6 | V38: 0 | W38: =P38+V38-U38 -> 0 | X38: SIGNED OFF
B39: 6 | D39: Fitter | E39: 1 | F39: 29 | G39: =IF(E39=1,IF(F39>=29,(F39-E39)+1),(F39-E39)+1) -> 29 | H39: =752*G39/30 -> 726.93333 | I39: =470*G39/30 -> 454.33333 | J39: =62.65*G39/30 -> 60.561667 | K39: =315.35*G39/30 -> 304.83833 | L39: =752/30*1 -> 25.066667 | M39: 0 | N39: 0 | O39: 37.5 | P39: =SUM(H39:O39) -> 1609.2333 | Q39: 200 | R39: =P39+V39-(Q39+S39+T39) -> 1409.2333 | S39: 0 | T39: 0 | U39: =SUM(Q39:T39) -> 1609.2333 | V39: 0 | W39: =P39+V39-U39 -> 0 | X39: SIGNED OFF
B40: 8 | D40: 4th.Engineer | E40: 1 | F40: 28 | G40: =IF(E40=1,IF(F40>=29,30,(F40-E40)+1),(F40-E40)+1) -> 28 | H40: =854*G40/30 -> 797.06667 | I40: =534*G40/30 -> 498.4 | J40: =71.17*G40/30 -> 66.425333 | K40: =540.83*G40/30 -> 504.77467 | L40: 0 | M40: 0 | N40: 0 | O40: 0 | P40: =SUM(H40:O40) -> 1866.6667 | Q40: 0 | R40: =P40+V40-(Q40+S40+T40) -> 1866.6667 | S40: 0 | T40: 0 | U40: =SUM(Q40:T40) -> 1866.6667 | V40: 0 | W40: =P40+V40-U40 -> 0 | X40: Promoted to 4E
C41: TOTAL (C) | H41: =SUM(H34:H40) -> 7683.6 | I41: =SUM(I34:I40) -> 4803.9333 | J41: =SUM(J34:J40) -> 770.526 | K41: =SUM(K34:K40) -> 26066.941 | L41: =SUM(L34:L40) -> 237.46667 | M41: =SUM(M34:M40) -> 0 | N41: =SUM(N34:N40) -> 92.78 | O41: =SUM(O34:O40) -> 75 | ... W41: =SUM(W34:W40) -> 46697.66
...

Sheet Salary Slip
B3: SALARY SLIP
B4: Vessel Name | C4: =+'PB '!D1 -> Vessel name | O4: 1
B6: Name | C6: =+'PB '!C7 -> 0 | H6: Rank | I6: Master
G9: Balance brought forward from previous month = | K9: US $ | L9: ='PB '!V7 -> 0 | R9: 31
B11: EARNINGS | D11: From | F11: To | H11: No.of days | I11: Wages p.m. | J11: US $
B12: Basic Wage | D12: ='PB '!E7 -> 28 | E12: ='PB '!C1 -> 0 | F12: ='PB '!F7 -> 31 | G12: ='PB '!C1 -> 0 | H12: ='PB '!G7 -> 4 | I12: 2267 | J12: =I12*H12/30 -> 302.26667 | Q12: =J25+J70+J117+J164+J210+J255+J302+J348+J394+J440+J486+J532+J579+J626+J672+J719+J767+J813+J860+J906+J953+J1000+J1047+J1096 -> 64968.94
B13: Fixed OT | D13: ='PB '!E7 -> 28 | E13: ='PB '!C1 -> 0 | F13: ='PB '!F7 -> 31 | G13: ='PB '!C1 -> 0 | H13: ='PB '!G7 -> 4 | I13: 1417 | J13: =I13*H13/30 -> 188.93333
B14: Leave wages | D14: ='PB '!E7 -> 28 | E14: ='PB '!C1 -> 0 | F14: ='PB '!F7 -> 31 | G14: ='PB '!C1 -> 0 | H14: ='PB '!G7 -> 4 | I14: 188.94 | J14: =I14*H14/30 -> 25.192
B15: Other /Seniority Allowances / Seniority | D15: ='PB '!E7 -> 28 | E15: ='PB '!C1 -> 0 | F15: ='PB '!F7 -> 31 | G15: ='PB '!C1 -> 0 | H15: ='PB '!G7 -> 4 | I15: 10127.06 | J15: =I15*H15/30 -> 1350.2747
B16: ='PB '!L5 -> Travel Wages | J16: ='PB '!L7 -> 75.566667
B17: Joining Expenses | J17: ='PB '!N7 -> 75.24
B18: HRA | J18: ='PB '!M7 -> 0
F19: Total Earnings ( A ) | J19: =SUM(J12:J18) -> 2017.4733 | K19: US $ | L19: =J19 -> 2017.4733
L20: =L9+L19 -> 2017.4733
B23: DEDUCTIONS
B24: Cash drawn on board | J24: ='PB '!Q7 -> 0
B25: Home Allotments | J25: ='PB '!R7 -> 7000
B26: Bond Stores | J26: ='PB '!S7 -> 0
B27: Radio bills | J27: 0
B28: Other Deductions | J28: ='PB '!T7 -> 0
F30: Total deductions ( B ) | J30: =SUM(J24:J28) -> 7000 | K30: US $ | L30: =J30 -> 7000
F33: FINAL BALANCE(A-B) | K33: US $ | L33: =L20-L30 -> -4982.5267
B37: I HEREBY DECLARE THAT THE BALANCE AMOUNT BROUGHT FORWARD FROM PREVIOUS MONTH IS
B38: IN MASTER'S CUSTODY AND I AGREE TO THE ABOVE FIGURES AND THAT THEY ARE CORRECT.
C39: SPECIAL ALLOTMENT OF 7000 USD WITH APPROVAL FROM CREWING HEAD.SAME TO BE ADJUSTED IN FEBRUARY 2026 WAGES.
B42: Signature of Seaman | I42: Signature : Master (With Ship's Stamp)
B44: Name | C44: =C6 -> 0 | I44: Name: | J44: =+'PB '!C7 -> 0
B49: SALARY SLIP | O49: 2
B50: Vessel Name | C50: =C4 -> Vessel name
B52: Name | C52: =+'PB '!C8 -> 0 | H52: Rank | I52: Ch.Officer
G55: Balance Carry forward To Next Month month = | K55: US $ | L55: ='PB '!V8 -> 0
B57: EARNINGS | D57: From | F57: To | H57: No.of days | I57: Wages p.m. | J57: US $
B58: Basic Wage | D58: ='PB '!E8 -> 1 | E58: ='PB '!C1 -> 0 | F58: ='PB '!F8 -> 31 | G58: ='PB '!C1 -> 0 | H58: =+'PB '!G8 -> 30 | I58: 1464 | J58: =I58*H58/30 -> 1464
B59: Fixed OT | D59: ='PB '!E8 -> 1 | E59: ='PB '!C1 -> 0 | F59: ='PB '!F8 -> 31 | G59: ='PB '!C1 -> 0 | H59: =+'PB '!G8 -> 30 | I59: 915 | J59: =I59*H59/30 -> 915
B60: Leave wages | D60: ='PB '!E8 -> 1 | E60: ='PB '!C1 -> 0 | F60: ='PB '!F8 -> 31 | G60: ='PB '!C1 -> 0 | H60: =+'PB '!G8 -> 30 | I60: 192.35 | J60: =I60*H60/30 -> 192.35
B61: Other /Seniority Allowances / Seniority | D61: ='PB '!E8 -> 1 | E61: ='PB '!C1 -> 0 | F61: ='PB '!F8 -> 31 | G61: ='PB '!C1 -> 0 | H61: =+'PB '!G8 -> 30 | I61: 8428.65 | J61: =I61*H61/30 -> 8428.65
B62: ='PB '!L5 -> Travel Wages | J62: ='PB '!L8 -> 0
B63: JOINING EXPENSES | J63: ='PB '!N8 -> 0
F64: Total Earnings ( A ) | J64: =SUM(J58:J63) -> 11000 | K64: US $ | L64: =J64 -> 11000
L65: =L64 -> 11000
...

Sheet Wage Statement
B3: Wage Statement
B4: Vessel Name | C4: SOFI 1 | G4: Port | H4: Dubai | J4: Date | L4: =L8 -> 44049
B6: Name | C6: ='PB '!#REF! -> #REF! | G6: Rank | H6: ='PB '!#REF! -> #REF! | J6: Date of Joining ship | L6: 43859
B8: Reason for discharge | D8: SIGN OFF | J8: Date of Discharge | L8: 44049
B10: TOTAL PERIOD ON BOARD | E10: =L8-L6 -> 190 | G10: DAYS | H10: Balance brought forward from previous month = | K10: US $ | L10: ='PB '!#REF! -> #REF!
B12: EARNINGS | D12: From | F12: To | H12: No.of days | I12: Wages p.m. | J12: US $
B13: Basic Wage | D13: 1 | E13: ='PB '!B1 -> 0 | F13: ='PB '!#REF! -> #REF! | G13: ='PB '!B1 -> 0 | H13: ='PB '!#REF! -> #REF! | I13: ='PB '!#REF! -> #REF! | J13: =I13*H13/30 -> #REF!
B14: Fixed OT | D14: 1 | E14: ='PB '!B1 -> 0 | F14: ='PB '!#REF! -> #REF! | G14: ='PB '!B1 -> 0 | H14: =H13 -> #REF! | I14: ='PB '!#REF! -> #REF! | J14: =I14*H14/30 -> #REF!
B15: Leave wages | D15: 1 | E15: ='PB '!B1 -> 0 | F15: ='PB '!#REF! -> #REF! | G15: ='PB '!B1 -> 0 | H15: =H14 -> #REF! | I15: ='PB '!#REF! -> #REF! | J15: =I15*H15/30 -> #REF!
B16: Other /Seniority Allowances | D16: 1 | E16: ='PB '!B1 -> 0 | F16: ='PB '!#REF! -> #REF! | G16: ='PB '!B1 -> 0 | H16: =H15 -> #REF! | I16: ='PB '!#REF! -> #REF! | J16: =I16*H16/30 -> #REF!
B17: Travel Wages/Other Earnings | I17: ='PB '!#REF! -> #REF! | J17: =I17 -> #REF!
I18: ='PB '!#REF! -> #REF! | J18: =I18 -> #REF!
F19: Total Earnings ( A ) | J19: =SUM(J13:J18) -> #REF! | K19: US $ | L19: =J19 -> #REF!
L20: =L10+L19 -> #REF!
B23: DEDUCTIONS
B24: Cash drawn on board | J24: ='PB '!#REF! -> #REF!
B25: Home Allotments | J25: ='PB '!#REF! -> #REF!
B26: Bond Stores | J26: ='PB '!#REF! -> #REF!
B27: Radio bills | J27: ='PB '!#REF! -> #REF!
B28: Others : | J28: ='PB '!#REF! -> #REF!
F30: Total deductions ( B ) | J30: =SUM(J24:J28) -> #REF! | K30: US $ | L30: =J30 -> #REF!
F33: FINAL BALANCE(A-B) | K33: US $ | L33: =L20-L30 -> #REF!
F36: Wages paid through cash by Master at Discharge from vessel | K36: US $ | L36: ='PB '!#REF! -> #REF!
F38: Total Balance Payable | K38: US $ | L38: =L33-L36 -> #REF!
B40: FINAL BALANCE to be remitted by Admiral Marine Service Limited Private
B41: ** Ensure FINAL BALANCE is NIL where full dues are paid on board. ;
B47: Signature of Seaman | I47: Signature : Master (With Ship's Stamp)
B49: Name | C49: =C6 -> #REF! | H49: Name: | I49: Capt. | J49: ='PB '!C7 -> 0
B53: Wage Statement
B54: Vessel Name | C54: =C4 -> SOFI 1 | G54: Port | H54: =H4 -> Dubai | J54: Date | L54: =L4 -> 44049
B56: Name | C56: ='PB '!#REF! -> #REF! | G56: Rank | H56: ='PB '!#REF! -> #REF! | J56: Date of Joining ship | L56: 43855
B58: Reason for discharge | D58: SIGN OFF | J58: Date of Discharge | L58: =L8 -> 44049
B60: TOTAL PERIOD ON BOARD | E60: =L58-L56 -> 194 | G60: DAYS | H60: Balance brought forward from previous month = | K60: US $ | L60: ='PB '!#REF! -> #REF!
B62: EARNINGS | D62: From | F62: To | H62: No.of days | I62: Wages p.m. | J62: US $
B63: Basic Wage | D63: 1 | E63: ='PB '!B1 -> 0 | F63: ='PB '!#REF! -> #REF! | G63: ='PB '!B1 -> 0 | H63: ='PB '!#REF! -> #REF! | I63: ='PB '!#REF! -> #REF! | J63: =I63*H63/30 -> #REF!
B64: Fixed OT | D64: 1 | E64: ='PB '!B1 -> 0 | F64: ='PB '!#REF! -> #REF! | G64: ='PB '!B1 -> 0 | H64: =H63 -> #REF! | I64: ='PB '!#REF! -> #REF! | J64: =I64*H64/30 -> #REF!
B65: Leave wages | D65: 1 | E65: ='PB '!B1 -> 0 | F65: ='PB '!#REF! -> #REF! | G65: ='PB '!B1 -> 0 | H65: =H64 -> #REF! | I65: ='PB '!#REF! -> #REF! | J65: =I65*H65/30 -> #REF!
B66: Other /Seniority Allowances | D66: 1 | E66: ='PB '!B1 -> 0 | F66: ='PB '!#REF! -> #REF! | G66: ='PB '!B1 -> 0 | H66: =H65 -> #REF! | I66: ='PB '!#REF! -> #REF! | J66: =I66*H66/30 -> #REF!
B67: Travel Wages/Other Earnings | I67: ='PB '!#REF! -> #REF! | J67: =I67 -> #REF!
I68: ='PB '!#REF! -> #REF! | J68: =I68 -> #REF!
...

Sheet Offsigners
B3: SALARY SLIP
B4: Vessel Name | C4: =+'PB '!D1 -> Vessel name
B6: Name | C6: ='PB '!C34 -> 0 | H6: Rank | I6: ='PB '!D34 -> Master
G9: Balance brought forward from previous month = | K9: US $ | L9: ='PB '!V34 -> 0
B11: EARNINGS | D11: From | F11: To | H11: No.of days | I11: Wages p.m. | J11: US $
B12: Basic Wage | D12: ='PB '!E34 -> 1 | E12: ='PB '!C1 -> 0 | F12: ='PB '!F34 -> 29 | G12: ='PB '!C1 -> 0 | H12: ='PB '!G34 -> 29 | I12: 2267 | J12: =I12/30*H12 -> 2191.4333
B13: Fixed OT | D13: ='PB '!E34 -> 1 | E13: ='PB '!C1 -> 0 | F13: ='PB '!F34 -> 29 | G13: ='PB '!C1 -> 0 | H13: ='PB '!G34 -> 29 | I13: 1417 | J13: =I13/30*H13 -> 1369.7667
B14: Leave wages | D14: ='PB '!E34 -> 1 | E14: ='PB '!C1 -> 0 | F14: ='PB '!F34 -> 29 | G14: ='PB '!C1 -> 0 | H14: ='PB '!G34 -> 29 | I14: 188.94 | J14: =I14/30*H14 -> 182.642
B15: Other /Seniority Allowances / Seniority | D15: ='PB '!E34 -> 1 | E15: ='PB '!C1 -> 0 | F15: ='PB '!F34 -> 29 | G15: ='PB '!C1 -> 0 | H15: ='PB '!G34 -> 29 | I15: 12127.06 | J15: =I15/30*H15 -> 11722.825
B16: ='PB '!L5 -> Travel Wages | J16: ='PB '!L34 -> 75.566667 | R16: =J25+J73+J120+J167+J213 -> 20390.907
B17: Sign Off Expenses | J17: ='PB '!N34 -> 92.78
B18: On Board Allowances | J18: ='PB '!O34 -> 0
F19: Total Earnings ( A ) | J19: =SUM(J12:J18) -> 15635.013 | K19: US $ | L19: =J19 -> 15635.013
L20: =L9+L19 -> 15635.013
B23: DEDUCTIONS
B24: Cash drawn on board | J24: ='PB '!Q34 -> 253
B25: Home Allotments | J25: ='PB '!R34 -> 15382.013
B26: Bond Stores | J26: ='PB '!S34 -> 0
B27: Radio bills | J27: 0
B28: Other Deductions | J28: ='PB '!T34 -> 0
J29: ='PB '!V34 -> 0
F30: Total deductions ( B ) | J30: =SUM(J24:J28) -> 15635.013 | K30: US $ | L30: =J30 -> 15635.013
F33: FINAL BALANCE(A-B) | K33: US $ | L33: =L20-L30 -> 0
B37: I HEREBY DECLARE THAT THE BALANCE AMOUNT BROUGHT FORWARD FROM PREVIOUS MONTH IS
B38: IN MASTER'S CUSTODY AND I AGREE TO THE ABOVE FIGURES AND THAT THEY ARE CORRECT.
B44: Signature of Seaman | I44: Signature : Master (With Ship's Stamp)
B46: Name | C46: =C6 -> 0 | I46: Name: | J46: ='PB '!C7 -> 0
B52: SALARY SLIP | O52: 2
B53: Vessel Name | C53: =C4 -> Vessel name
B55: Name | C55: =+'PB '!C35 -> 0 | H55: Rank | I55: ='PB '!D35 -> Deck Cadet
G58: Balance Carry forward To Next Month month = | K58: US $ | L58: ='PB '!V35 -> 0
B60: EARNINGS | D60: From | F60: To | H60: No.of days | I60: Wages p.m. | J60: US $
B61: Basic Wage | D61: ='PB '!E35 -> 1 | E61: ='PB '!C1 -> 0 | F61: ='PB '!F35 -> 29 | G61: ='PB '!C1 -> 0 | H61: ='PB '!G35 -> 29 | I61: 199 | J61: =I61/30*H61 -> 192.36667
B62: Fixed OT | D62: =D61 -> 1 | E62: ='PB '!C1 -> 0 | F62: ='PB '!F35 -> 29 | G62: ='PB '!C1 -> 0 | H62: ='PB '!G35 -> 29 | I62: 125 | J62: =I62/30*H62 -> 120.83333
B63: Leave wages | D63: =D61 -> 1 | E63: ='PB '!C1 -> 0 | F63: ='PB '!F35 -> 29 | G63: ='PB '!C1 -> 0 | H63: ='PB '!G35 -> 29 | I63: 26 | J63: =I63/30*H63 -> 25.133333
B64: Other /Seniority Allowances / Seniority | D64: =D61 -> 1 | E64: ='PB '!C1 -> 0 | F64: ='PB '!F35 -> 29 | G64: ='PB '!C1 -> 0 | H64: ='PB '!G35 -> 29 | I64: 0 | J64: =I64/30*H64 -> 0
B65: ='PB '!L5 -> Travel Wages | J65: ='PB '!L35 -> 6.6333333
B66: On Board Allowances | J66: 0
F67: Total Earnings ( A ) | J67: =SUM(J61:J66) -> 344.96667 | K67: US $ | L67: =J67 -> 344.96667
L68: =L67 -> 344.96667
...

Sheet ALLOWANCE 
B3: Company name
B4: Vessel name
B5: Allowance Brk Up
B6: ='PB '!C1 -> 0
B7: S.No | C7: Name of Crew | D7: Rank | E7: ME SCAVANGE SPACE, UP SPACE CLEANING AND EXH GAS BOILER CLEANING ALLOWANCE IN USD | F7: FW STBD SIDE TANK CLEANING | G7: Short manning Allowance | H7: Total
B8: 1 | C8: ='PB '!C11 -> 0 | D8: ='PB '!D11 -> Deck Cadet | E8: 0 | F8: 0 | G8: 0 | H8: =E8+F8+G8 -> 0
B9: 2 | C9: ='PB '!C19 -> 0 | D9: ='PB '!D19 -> Pumpman | E9: 0 | F9: 0 | G9: 0 | H9: =E9+F9+G9 -> 0
B10: 3 | C10: ='PB '!C20 -> 0 | D10: ='PB '!D20 -> Bosun | E10: 0 | F10: 16.6 | G10: 0 | H10: =E10+F10+G10 -> 16.6
B11: 4 | C11: RAISH HUSSAIN | D11: ='PB '!D21 -> AB 1 | E11: 0 | F11: 16.6 | G11: 0 | H11: =E11+F11+G11 -> 16.6
B12: 5 | C12: SATINDER SINGH | D12: ='PB '!D22 -> AB 2 | E12: 0 | F12: 16.6 | G12: 0 | H12: =E12+F12+G12 -> 16.6
B13: 6 | C13: SALSON SELVAM | D13: ='PB '!D23 -> AB 3 | E13: 0 | F13: 16.6 | G13: 0 | H13: =E13+F13+G13 -> 16.6
B14: 7 | C14: KISHOR RAJU | D14: ='PB '!D24 -> OS 1 | E14: 0 | F14: 16.8 | G14: 0 | H14: =E14+F14+G14 -> 16.8
B15: 8 | C15: GOPINADH KARUKU | D15: OS 2 | E15: 0 | F15: 16.8 | G15: 0 | H15: =E15+F15+G15 -> 16.8
B16: 9 | C16: ='PB '!C26 -> 0 | D16: ='PB '!D26 -> Oiler 1 | E16: 37.5 | F16: 0 | G16: 0 | H16: =E16+F16+G16 -> 37.5
B17: 10 | C17: ='PB '!C27 -> 0 | D17: ='PB '!D27 -> Oiler 2 | E17: 37.5 | F17: 0 | G17: 0 | H17: =E17+F17+G17 -> 37.5
B18: 11 | C18: ='PB '!C38 -> 0 | D18: ='PB '!D28 -> Oiler 3 | E18: 37.5 | F18: 0 | G18: 0 | H18: =E18+F18+G18 -> 37.5
B19: 12 | C19: ='PB '!C39 -> 0 | D19: ='PB '!D29 -> Fitter | E19: 37.5 | F19: 0 | G19: 0 | H19: =E19+F19+G19 -> 37.5
B20: Total | E20: =SUM(E8:E19) -> 150 | F20: =SUM(F8:F19) -> 100 | G20: =SUM(G9:G19) -> 0 | H20: =SUM(H8:H19) -> 250
E30: ='PB '!C7 -> 0
E31: MASTER, vessel name

Sheet Allotment Sheet
A1: HOME ALLOTMENT FOR SEAFARER OF THE VESSEL - xxxxx
C2: MONTH : | D2: ='PB '!C1 -> 0
A3: Sl No | B3: CREW NAME | C3: RANK | D3: BENIFICIARY NAME | E3: BENIFICIARY BANK ACCOUNT NO | F3: BENEFICIARY BANK NAME | G3: BENIFICIARY BANK ADDRESS | H3: IFSC CODE | I3: ALLOTMENT AMOUNT IN USD | J3: CURRENCY TO BE SEND | K3: RATE | L3: PAYOUT CCY CODE | M3: PAY OUT AMOUNT | N3: AED | O3: CHGS | P3: TOTAL | Q3: SIGN
A4: 1 | B4: ='PB '!C7 -> 0 | C4: ='PB '!D7 -> Master | I4: ='PB '!R7 -> 7000 | J4: Editable
A5: 2 | B5: ='PB '!C8 -> 0 | C5: ='PB '!D8 -> Ch.Officer | I5: ='PB '!R8 -> 11000 | J5: Editable
A6: 3 | B6: ='PB '!C9 -> 0 | C6: Adtnl Ch.Officer | I6: ='PB '!R9 -> 5050 | J6: Editable
A7: 4 | B7: ='PB '!C10 -> 0 | C7: 2nd Officer | I7: ='PB '!R10 -> 4193.08 | J7: Editable
A8: 5 | B8: ='PB '!C11 -> 0 | C8: ='PB '!D11 -> Deck Cadet | I8: ='PB '!R11 -> 86.03 | J8: Editable
A9: 6 | B9: ='PB '!C12 -> 0 | C9: ='PB '!D12 -> Ch.Engineer | I9: ='PB '!R12 -> 2163.0167 | J9: Editable
A10: 7 | B10: ='PB '!C13 -> 0 | C10: ='PB '!D13 -> 2nd Engineer | I10: ='PB '!R13 -> 12500 | J10: Editable
A11: 8 | B11: ='PB '!C14 -> 0 | C11: ='PB '!D14 -> 3rd.Engineer | I11: ='PB '!R14+'PB '!R40 -> 2166.6667 | J11: Editable
A12: 9 | B12: ='PB '!C15 -> 0 | C12: ='PB '!D15 -> 4th Engineer | I12: ='PB '!R15 -> 375.13333 | J12: Editable
A13: 10 | B13: ='PB '!C16 -> 0 | C13: ='PB '!D16 -> TME | I13: ='PB '!R16 -> 350 | J13: Editable
A14: 11 | B14: ='PB '!C17 -> 0 | C14: ='PB '!D17 -> Eletrical Officer | I14: ='PB '!R17 -> 6472.32 | J14: Editable
A15: 12 | B15: ='PB '!C19 -> 0 | C15: ='PB '!D19 -> Pumpman | I15: ='PB '!R19 -> 2800 | J15: Editable
A16: 13 | B16: ='PB '!C20 -> 0 | C16: ='PB '!D20 -> Bosun | I16: ='PB '!R20 -> 2016.6 | J16: Editable
A17: 14 | B17: ='PB '!C21 -> 0 | C17: ='PB '!D21 -> AB 1 | I17: ='PB '!R21 -> 1566.6 | J17: Editable
A18: 15 | B18: ='PB '!C22 -> 0 | C18: ='PB '!D22 -> AB 2 | I18: ='PB '!R22 -> 1466.6 | J18: Editable
A19: 16 | B19: ='PB '!C23 -> 0 | C19: ='PB '!D23 -> AB 3 | I19: ='PB '!R23 -> 1316.6 | J19: Editable
A20: 17 | B20: ='PB '!C24 -> 0 | C20: ='PB '!D24 -> OS 1 | I20: ='PB '!R24 -> 517.8 | J20: Editable
A21: 18 | B21: ='PB '!C25 -> 0 | C21: ='PB '!D25 -> OS 2 | I21: ='PB '!R25 -> 566.8 | J21: Editable
A22: 19 | B22: ='PB '!C26 -> 0 | C22: ='PB '!D26 -> Oiler 1 | I22: ='PB '!R26 -> 1480.58 | J22: Editable
A23: 20 | B23: ='PB '!C27 -> 0 | C23: ='PB '!D27 -> Oiler 2 | I23: ='PB '!R27 -> 1237.5 | J23: Editable
A24: 21 | B24: ='PB '!C28 -> 0 | C24: ='PB '!D28 -> Oiler 3 | I24: ='PB '!R28 -> 321.88 | J24: Editable
A25: 22 | B25: ='PB '!C29 -> 0 | C25: ='PB '!D29 -> Fitter | I25: ='PB '!R29 -> 238.4 | J25: Editable
A26: 23 | B26: ='PB '!C30 -> 0 | C26: ='PB '!D30 -> Chief Cook | I26: ='PB '!R30 -> 1500 | J26: Editable
A27: 24 | B27: ='PB '!C31 -> 0 | C27: ='PB '!D31 -> GS | I27: ='PB '!R31 -> 450 | J27: Editable
A28: OFF SIGNERS DURING THE MONTH
A29: 1 | B29: ='PB '!C34 -> 0 | C29: ='PB '!D34 -> Master | I29: ='PB '!R34 -> 15382.013 | J29: Editable | Q29: SIGNED OFF
A30: 2 | B30: ='PB '!C35 -> 0 | C30: ='PB '!D35 -> Deck Cadet | I30: ='PB '!R35 -> 344.96667 | J30: Editable | Q30: SIGNED OFF
A31: 3 | B31: ='PB '!C36 -> 0 | C31: ='PB '!D36 -> Ch.Engineer | I31: ='PB '!R36 -> 0 | J31: Editable | Q31: SIGNED OFF
A32: 4 | B32: ='PB '!C37 -> 0 | C32: ='PB '!D37 -> 3rd.Engineer | I32: ='PB '!R37 -> 4263.9267 | J32: Editable | Q32: SIGNED OFF
A33: 5 | B33: ='PB '!C38 -> 0 | C33: ='PB '!D38 -> Oiler 3 | I33: ='PB '!R38 -> 916.6 | J33: Editable | Q33: SIGNED OFF
A34: 6 | B34: ='PB '!C39 -> 0 | C34: ='PB '!D39 -> Fitter | I34: ='PB '!R39 -> 1409.2333 | J34: Editable | Q34: SIGNED OFF
G35: TOTAL = | I35: =SUM(I4:I34) -> 89152.347
I44: ='PB '!C7 -> 0
I45: MASTER / MT ALMA

Sheet Discretionary Account
A1: M.V.ONYX 1
G2: DATE: | H2: 30.06.2017
A3: DISCRETIONARY ACCOUNT- June 2017
A5: S. No. | B5: Date | C5: Voucher | D5: Port | E5: Details | G5: Received | H5: Expenditure
E6: Balance B/F from MAY' 2017 | G6: 0
F8: 1000
G33: =SUM(G6:G30) -> 0 | H33: =SUM(H7:H30) -> 0
E34: Spent on board as of 30.06.2017 | F34: 28.2.15 | G34: =H33 -> 0
E35: Balance on board as of 30.06.2017 | F35: 28.2.15 | G35: =(G33-G34) -> 0
G41: Capt.FRANKLIN WILFRED
G42: Master

Sheet MCA
A1: Vessel Name
A3: MASTER CASH ACCOUNT JANUARY' 2026
A5: Date | B5: Voucher No | C5: Details | D5: Received USD | E5: Expenditure USD
A6: 01.01.2026 | C6: Balance From Last month (DEC' 2025) | D6: 21565.77
A7: 17.01.2026 | C7: Paid as cash advance to Officer and crew on board | E7: 2153
A8: 18.01.2026 | C8: Crew Welfare for the Month of JANUARY-2026 | E8: 200
C12: TOTAL | D12: =SUM(D6:D11) -> 21565.77 | E12: =SUM(E6:E11) -> 2353
C13: CASH ON BOARD | D13: =D12-E12 -> 19212.77
C19: ='PB '!C7 -> 0
C20: Master, MT ALMA

Sheet Calling - Chart Cards Statement
B2: ALMA CREW CALLING CARD
B4: ITEMS | I4: TOTAL | J4: SIGNATURE
B6: PRICE IN USD | D6: 32
A7: NO. | B7: NAME | C7: RANK
A8: 1 | B8: =+'PB '!C7 -> 0 | C8: =+'PB '!D7 -> Master | D8: 0 | I8: =(($D$6*D8)+($E$6*E8)+($F$6*F8)+($G$6*G8)+($H$6*H8)) -> 0
A9: 2 | B9: =+'PB '!C8 -> 0 | C9: =+'PB '!D8 -> Ch.Officer | D9: 0 | I9: =(($D$6*D9)+($E$6*E9)+($F$6*F9)+($G$6*G9)+($H$6*H9)) -> 0
A10: 3 | B10: =+'PB '!C9 -> 0 | C10: =+'PB '!D9 -> Adtnl Ch.Officer | D10: 0 | I10: =(($D$6*D10)+($E$6*E10)+($F$6*F10)+($G$6*G10)+($H$6*H10)) -> 0
A11: 4 | B11: =+'PB '!C10 -> 0 | C11: =+'PB '!D10 -> 2nd Officer | D11: 0 | I11: =(($D$6*D11)+($E$6*E11)+($F$6*F11)+($G$6*G11)+($H$6*H11)) -> 0
A12: 5 | B12: =+'PB '!C11 -> 0 | C12: =+'PB '!D11 -> Deck Cadet | D12: 0 | I12: =(($D$6*D12)+($E$6*E12)+($F$6*F12)+($G$6*G12)+($H$6*H12)) -> 0
A13: 6 | B13: =+'PB '!C12 -> 0 | C13: =+'PB '!D12 -> Ch.Engineer | D13: 0 | I13: =(($D$6*D13)+($E$6*E13)+($F$6*F13)+($G$6*G13)+($H$6*H13)) -> 0
A14: 7 | B14: =+'PB '!C13 -> 0 | C14: =+'PB '!D13 -> 2nd Engineer | D14: 0 | I14: =(($D$6*D14)+($E$6*E14)+($F$6*F14)+($G$6*G14)+($H$6*H14)) -> 0
A15: 8 | B15: =+'PB '!C14 -> 0 | C15: =+'PB '!D14 -> 3rd.Engineer | D15: 0 | I15: =(($D$6*D15)+($E$6*E15)+($F$6*F15)+($G$6*G15)+($H$6*H15)) -> 0
A16: 9 | B16: =+'PB '!C15 -> 0 | C16: =+'PB '!D15 -> 4th Engineer | D16: 0 | I16: =(($D$6*D16)+($E$6*E16)+($F$6*F16)+($G$6*G16)+($H$6*H16)) -> 0
A17: 10 | B17: =+'PB '!C19 -> 0 | C17: =+'PB '!D19 -> Pumpman | D17: 0 | I17: =(($D$6*D17)+($E$6*E17)+($F$6*F17)+($G$6*G17)+($H$6*H17)) -> 0
A18: 11 | B18: =+'PB '!C16 -> 0 | C18: =+'PB '!D16 -> TME | D18: 0 | I18: =(($D$6*D18)+($E$6*E18)+($F$6*F18)+($G$6*G18)+($H$6*H18)) -> 0
A19: 12 | B19: =+'PB '!C17 -> 0 | C19: =+'PB '!D17 -> Eletrical Officer | D19: 0 | I19: =(($D$6*D19)+($E$6*E19)+($F$6*F19)+($G$6*G19)+($H$6*H19)) -> 0
A20: 13 | B20: =+'PB '!C20 -> 0 | C20: =+'PB '!D20 -> Bosun | D20: 0 | I20: =(($D$6*D20)+($E$6*E20)+($F$6*F20)+($G$6*G20)+($H$6*H20)) -> 0
A21: 14 | B21: =+'PB '!C21 -> 0 | C21: =+'PB '!D21 -> AB 1 | D21: 0 | I21: =(($D$6*D21)+($E$6*E21)+($F$6*F21)+($G$6*G21)+($H$6*H21)) -> 0
A22: 15 | B22: =+'PB '!C22 -> 0 | C22: =+'PB '!D22 -> AB 2 | D22: 0 | I22: =(($D$6*D22)+($E$6*E22)+($F$6*F22)+($G$6*G22)+($H$6*H22)) -> 0
A23: 16 | B23: =+'PB '!C23 -> 0 | C23: =+'PB '!D23 -> AB 3 | D23: 0 | I23: =(($D$6*D23)+($E$6*E23)+($F$6*F23)+($G$6*G23)+($H$6*H23)) -> 0
A24: 17 | B24: =+'PB '!C24 -> 0 | C24: =+'PB '!D24 -> OS 1 | D24: 0 | I24: =(($D$6*D24)+($E$6*E24)+($F$6*F24)+($G$6*G24)+($H$6*H24)) -> 0
A25: 18 | B25: =+'PB '!C25 -> 0 | C25: =+'PB '!D25 -> OS 2 | D25: 0 | I25: =(($D$6*D25)+($E$6*E25)+($F$6*F25)+($G$6*G25)+($H$6*H25)) -> 0
A26: 19 | B26: =+'PB '!C26 -> 0 | C26: =+'PB '!D26 -> Oiler 1 | D26: 0 | I26: =(($D$6*D26)+($E$6*E26)+($F$6*F26)+($G$6*G26)+($H$6*H26)) -> 0
A27: 20 | B27: =+'PB '!C27 -> 0 | C27: =+'PB '!D27 -> Oiler 2 | D27: 0 | I27: =(($D$6*D27)+($E$6*E27)+($F$6*F27)+($G$6*G27)+($H$6*H27)) -> 0
A28: 21 | B28: =+'PB '!C28 -> 0 | C28: =+'PB '!D28 -> Oiler 3 | D28: 0 | I28: =(($D$6*D28)+($E$6*E28)+($F$6*F28)+($G$6*G28)+($H$6*H28)) -> 0
A29: 22 | B29: =+'PB '!C29 -> 0 | C29: =+'PB '!D29 -> Fitter | D29: 0 | I29: =(($D$6*D29)+($E$6*E29)+($F$6*F29)+($G$6*G29)+($H$6*H29)) -> 0
A30: 23 | B30: =+'PB '!C30 -> 0 | C30: =+'PB '!D30 -> Chief Cook | D30: 0 | I30: =(($D$6*D30)+($E$6*E30)+($F$6*F30)+($G$6*G30)+($H$6*H30)) -> 0
A32: TOTAL CONSUMPTION BY CREW /OFFICERS | D32: =SUM(D8:D31) -> 0 | E32: =SUM(E8:E31) -> 0 | F32: =SUM(F8:F31) -> 0 | G32: =SUM(G8:G31) -> 0 | H32: =SUM(H8:H31) -> 0 | I32: =SUM(I8:I31) -> 0
A35: CHARTERERS
A36: 1 | D36: 0 | I36: =(($D$6*D36)+($E$6*E36)+($F$6*F36)+($G$6*G36)+($H$6*H36)) -> 0
A37: 2 | I37: =(($D$6*D37)+($E$6*E37)+($F$6*F37)+($G$6*G37)+($H$6*H37)) -> 0
A38: 3 | I38: =(($D$6*D38)+($E$6*E38)+($F$6*F38)+($G$6*G38)+($H$6*H38)) -> 0
A39: 4 | I39: =(($D$6*D39)+($E$6*E39)+($F$6*F39)+($G$6*G39)+($H$6*H39)) -> 0
A40: 5 | I40: =(($D$6*D40)+($E$6*E40)+($F$6*F40)+($G$6*G40)+($H$6*H40)) -> 0
A42: TOTAL CONSUMPTION - CHARTERERS ACCOUNT | D42: =SUM(D36:D40) -> 0 | E42: =SUM(E36:E40) -> 0 | F42: =SUM(F36:F40) -> 0 | G42: =SUM(G36:G40) -> 0 | H42: =SUM(H36:H40) -> 0 | I42: =SUM(I36:I40) -> 0 | J42: =SUM(J36:J40) -> 0
A44: OWNERS
A45: 1 | I45: =(($D$6*D45)+($E$6*E45)+($F$6*F45)+($G$6*G45)+($H$6*H45)) -> 0
A46: 2 | I46: =(($D$6*D46)+($E$6*E46)+($F$6*F46)+($G$6*G46)+($H$6*H46)) -> 0
A48: TOTAL CONSUMPTION - OWNERS ACCOUNT | D48: =SUM(D45:D46) -> 0 | E48: =SUM(E45:E46) -> 0 | F48: =SUM(F45:F46) -> 0 | G48: =SUM(G45:G46) -> 0 | H48: =SUM(H45:H46) -> 0 | I48: =SUM(I45:I46) -> 0 | J48: =SUM(J45:J46) -> 0
A50: TOTAL CONSUMPTION - OVERALL | D50: =+D32+D42+D48 -> 0 | E50: =+E33+E42+E48 -> 0 | F50: =F33+F42+F48 -> 0 | G50: =+G33+G42+G48 -> 0 | H50: =+H33+H42+H48 -> 0 | I50: =+I32+I42+I48 -> 0 | J50: =+J33+J42+J48 -> 0

Sheet Welfare Account
A1: Vessel Name
A3: WELFARE ACCOUNT FOR THE MONTH OF - JANUARY'2026
A5: Date | B5: Voucher No | C5: Details | D5: Received USD | E5: Expenditure USD
A6: 01.01.2026 | C6: B/F From Last Month DEC' 2025 | D6: 286
A7: 02.01.2026 | C7: Paid to purchase Christmas & New year party items for crew welfare | E7: 200
A8: 18.01.2026 | C8: Crew Welfare for the Month of JANUARY 2026 | D8: 200
A9: 29.01.2026 | C9: Paid to purchase Cricket Balls for Crew Welfare | E9: 100
C12: TOTAL | D12: =SUM(D6:D11) -> 486 | E12: =SUM(E6:E11) -> 300
C14: CASH ON BOARD | D14: =D12-E12 -> 186
C20: ='PB '!C7 -> 0
C21: Master, Vessel Name
