Workbook
Name anchor: [1]Sheet2!#REF!
Name ht: [1]Sheet2!#REF!
Name PRINTAREA: #REF!
Name wdt: [1]Sheet2!#REF!
Name xxx: [1]Sheet2!#REF!

Sheet Provisions Covering Sheet
A2: Vessel Name
C4: Statement for Provisions consumption for : | J4: 46021
C7: Provisions balance brought forward | G7: =CONSOLIDATED!E321 -> 13303.125 | I7: Consumption as per attached | N7: =CONSOLIDATED!Y321 -> 7221.0792
C8: from last month | I8: Statement:
I9: Transport | N9: =G16+G17+G18 -> 0
I10: Less: Outport messing expenses | N10: =+'OUTPORT MESSING'!I16 -> 0
I11: (for Pilot / Workshop / Superintendent / Immigration / Customs etc. - actual cost)
C12: Provsions received during the month | G12: =CONSOLIDATED!J322 -> 0
I13: Provision value consumed for Ship's crew: | N13: =N7-N10 -> 7221.0792
C16: Transport (delivery Charge)= | E16: 1. Transportation + boat- | F16: = | I16: Value of Provisions balance carried forward : | N16: =G20-N7-N9 -> 6082.0456
E17: 2. Authorities and Terminal Fee- | J17: as on | K17: 46022
E18: 3. Transportation Fee-
E20: Total: | G20: =SUM(G7:G19) -> 13303.125 | K20: Total: | N20: =SUM(N7+N16+N9) -> 13303.125
G23: Per day per head expense: | J23: =+N7/H29 -> 9.7057516
D26: No. of crew x days of the month: | H26: ='Shipstaff Manday Calculation'!F34 -> 744
D27: Outport mandays | H27: ='OUTPORT MESSING'!H16 -> 0
D29: Total no. of man days for the month | H29: =H26+H27+H28 -> 744
L31: Master name
L32: Vessel Name

Sheet Shipstaff Manday Calculation
A1: Vessel Name
A2: Statement of man days for the month | D2: ='Provisions Covering Sheet'!J4 -> 46021
A4: No. | B4: Ranks | C4: From | D4: To | E4: Number of meals | F4: No. of days
A5: 1 | B5: Master | C5: 01.12.2025 | D5: 31.12.2025 | F5: 31 | G5: Onboard for full month calcuate as per the crew list onbaord
A6: 2 | B6: CH OFFICER | C6: 01.12.2025 | D6: 31.12.2025 | F6: 31
A7: 3 | B7: Adtnl CO | C7: 01.12.2025 | D7: 31.12.2025 | F7: 31
A8: 4 | B8: 2nd Officer | C8: 01.12.2025 | D8: 31.12.2025 | F8: 31
A9: 5 | B9: Dack Cadet | C9: 01.12.2025 | D9: 31.12.2025 | F9: 31
A10: 6 | B10: Ch.Eng. | C10: 01.12.2025 | D10: 31.12.2025 | F10: 31
A11: 7 | B11: 2nd Engineer | C11: 01.12.2025 | D11: 31.12.2025 | F11: 31
A12: 8 | B12: 3rd Engineer | C12: 01.12.2025 | D12: 31.12.2025 | F12: 31
A13: 9 | B13: 4th Engineer | C13: 01.12.2025 | D13: 31.12.2025 | F13: 31
A14: 10 | B14: Trainee Marine Engineer | C14: 01.12.2025 | D14: 31.12.2025 | F14: 31
A15: 11 | B15: Electrical Officer | C15: 01.12.2025 | D15: 31.12.2025 | F15: 31
A16: 12 | B16: BOSUN | C16: 01.12.2025 | D16: 31.12.2025 | F16: 31
A17: 13 | B17: AB 1 | C17: 01.12.2025 | D17: 31.12.2025 | F17: 31
... A28: 24 | B28: Trainee General Steward | C28: 01.12.2025 | D28: 31.12.2025 | F28: 31
B30: OFFSIGNERS
A31: 1
A32: 2
C34: Total Mandays: | F34: =SUM(F5:F33) -> 744
C44: ='Provisions Covering Sheet'!L31 -> Master name
D45: ='Provisions Covering Sheet'!L32 -> Vessel Name

Sheet CONSOLIDATED
J1: =E321 -> 13303.125
S3: (ALL AMOUNTS IN US DOLLARS)
A4: RECEIPT & CONSUMPTION STATEMENT FOR THE MONTH OF | F4: ='Provisions Covering Sheet'!J4 -> 46021 | V4: =S321-Y321 -> 6082.0456
A5: ='Provisions Covering Sheet'!J23 -> 9.7057516 | C5: MT ALMA | I5: =I321 -> 0 | M5: =M321 -> 0 | V5: =+V321 -> 6082.0456 | Y5: =Y321 -> 7221.0792
A6: ITEM | B6: UNIT | C6: OPENING ROB | F6: 1 PURCHASE | J6: 2 PURCHASE | N6: 3 PURCHASE | Q6: TOTAL MONTHLY ROB | T6: MONTH END ROB | W6: CONSUMPTION
C7: Weight | D7: Unit | E7: Total | F7: Weight | G7: UNIT SGD | H7: UNIT USD | I7: USD | J7: Weight | K7: UNIT AED | L7: UNIT USD | M7: USD | N7: Weight | O7: Unit | P7: Total | Q7: Weight | R7: Unit | S7: Total | T7: Weight | U7: Unit | V7: Total | W7: Weight | X7: Unit | Y7: Total
A8: INDIAN GOAT WHOLE(12-15 KG ZABIA HALAl) | B8: KGS | C8: 30.58 | D8: 7.6923077 | E8: =C8*D8 -> 235.23077 | H8: =G8/1.3 -> 0 | I8: =F8*H8 -> 0 | M8: =J8*L8 -> 0 | Q8: =C8+F8+J8+N8 -> 30.58 | R8: =IF(Q8=0,"0.00",S8/Q8) -> 7.6923077 | S8: =E8+I8+M8+P8 -> 235.23077 | T8: 12 | U8: =R8 -> 7.6923077 | V8: =T8*U8 -> 92.307692 | W8: =Q8-T8 -> 18.58 | X8: =R8 -> 7.6923077 | Y8: =W8*X8 -> 142.92308
A9: MUTTON BONELESS LEG | B9: KGS | C9: 20 | D9: 11.115385 | E9: =C9*D9 -> 222.30769 | H9: =G9/1.3 -> 0 | I9: =F9*H9 -> 0 | M9: =J9*L9 -> 0 | Q9: =C9+F9+J9+N9 -> 20 | R9: =IF(Q9=0,"0.00",S9/Q9) -> 11.115385 | S9: =E9+I9+M9+P9 -> 222.30769 | T9: 12 | U9: =R9 -> 11.115385 | V9: =T9*U9 -> 133.38462 | W9: =Q9-T9 -> 8 | X9: =R9 -> 11.115385 | Y9: =W9*X9 -> 88.923077
A10: CHICKEN WHOLE | B10: KGS | C10: 160 | D10: 2.4537326 | E10: =C10*D10 -> 392.59722 | H10: =G10/1.3 -> 0 | I10: =F10*H10 -> 0 | M10: =J10*L10 -> 0 | Q10: =C10+F10+J10+N10 -> 160 | R10: =IF(Q10=0,"0.00",S10/Q10) -> 2.4537326 | S10: =E10+I10+M10+P10 -> 392.59722 | T10: 60 | U10: =R10 -> 2.4537326 | V10: =T10*U10 -> 147.22396 | W10: =Q10-T10 -> 100 | X10: =R10 -> 2.4537326 | Y10: =W10*X10 -> 245.37326
A11: CHICKEN BREAST | B11: KGS | C11: 18 | D11: 3.8076923 | E11: =C11*D11 -> 68.538462 | H11: =G11/1.3 -> 0 | I11: =F11*H11 -> 0 | M11: =J11*L11 -> 0 | Q11: =C11+F11+J11+N11 -> 18 | R11: =IF(Q11=0,"0.00",S11/Q11) -> 3.8076923 | S11: =E11+I11+M11+P11 -> 68.538462 | T11: 10 | U11: =R11 -> 3.8076923 | V11: =T11*U11 -> 38.076923 | W11: =Q11-T11 -> 8 | X11: =R11 -> 3.8076923 | Y11: =W11*X11 -> 30.461538
A12: CHICKEN LEG DRUMSTICK | B12: KGS | C12: 40 | D12: 2.3203578 | E12: =C12*D12 -> 92.814311 | H12: =G12/1.3 -> 0 | I12: =F12*H12 -> 0 | M12: =J12*L12 -> 0 | Q12: =C12+F12+J12+N12 -> 40 | R12: =IF(Q12=0,"0.00",S12/Q12) -> 2.3203578 | S12: =E12+I12+M12+P12 -> 92.814311 | T12: 20 | U12: =R12 -> 2.3203578 | V12: =T12*U12 -> 46.407155 | W12: =Q12-T12 -> 20 | X12: =R12 -> 2.3203578 | Y12: =W12*X12 -> 46.407155
A13: CHICKEN WINGS | B13: KGS | D13: 0.00 | E13: =C13*D13 -> 0 | H13: =G13/1.3 -> 0 | I13: =F13*H13 -> 0 | M13: =J13*L13 -> 0 | Q13: =C13+F13+J13+N13 -> 0 | R13: =IF(Q13=0,"0.00",S13/Q13) -> 0.00 | S13: =E13+I13+M13+P13 -> 0 | U13: =R13 -> 0.00 | V13: =T13*U13 -> 0 | W13: =Q13-T13 -> 0 | X13: =R13 -> 0.00 | Y13: =W13*X13 -> 0
A14: CHICKEN SAUSAGES | B14: KGS | C14: 20 | D14: 2.5185927 | E14: =C14*D14 -> 50.371854 | H14: =G14/1.3 -> 0 | I14: =F14*H14 -> 0 | M14: =J14*L14 -> 0 | Q14: =C14+F14+J14+N14 -> 20 | R14: =IF(Q14=0,"0.00",S14/Q14) -> 2.5185927 | S14: =E14+I14+M14+P14 -> 50.371854 | T14: 15 | U14: =R14 -> 2.5185927 | V14: =T14*U14 -> 37.778891 | W14: =Q14-T14 -> 5 | X14: =R14 -> 2.5185927 | Y14: =W14*X14 -> 12.592964
A15: CHICKEN NUGGETS 1KG | B15: KGS | C15: 12 | D15: 3.6187152 | E15: =C15*D15 -> 43.424582 | H15: =G15/1.3 -> 0 | I15: =F15*H15 -> 0 | M15: =J15*L15 -> 0 | Q15: =C15+F15+J15+N15 -> 12 | R15: =IF(Q15=0,"0.00",S15/Q15) -> 3.6187152 | S15: =E15+I15+M15+P15 -> 43.424582 | T15: 7 | U15: =R15 -> 3.6187152 | V15: =T15*U15 -> 25.331006 | W15: =Q15-T15 -> 5 | X15: =R15 -> 3.6187152 | Y15: =W15*X15 -> 18.093576
A16: KING FISH | B16: KGS | C16: 25 | D16: 4.158387 | E16: =C16*D16 -> 103.95967 | H16: =G16/1.3 -> 0 | I16: =F16*H16 -> 0 | M16: =J16*L16 -> 0 | Q16: =C16+F16+J16+N16 -> 25 | R16: =IF(Q16=0,"0.00",S16/Q16) -> 4.158387 | S16: =E16+I16+M16+P16 -> 103.95967 | T16: 12 | U16: =R16 -> 4.158387 | V16: =T16*U16 -> 49.900643 | W16: =Q16-T16 -> 13 | X16: =R16 -> 4.158387 | Y16: =W16*X16 -> 54.05903
A17: FISH FILLET | B17: KGS | C17: 15 | D17: 3.5133201 | E17: =C17*D17 -> 52.699802 | H17: =G17/1.3 -> 0 | I17: =F17*H17 -> 0 | M17: =J17*L17 -> 0 | Q17: =C17+F17+J17+N17 -> 15 | R17: =IF(Q17=0,"0.00",S17/Q17) -> 3.5133201 | S17: =E17+I17+M17+P17 -> 52.699802 | T17: 8 | U17: =R17 -> 3.5133201 | V17: =T17*U17 -> 28.106561 | W17: =Q17-T17 -> 7 | X17: =R17 -> 3.5133201 | Y17: =W17*X17 -> 24.593241
A18: ROHU FISH | B18: KGS | C18: 2 | D18: 3.14 | E18: =C18*D18 -> 6.28 | H18: =G18/1.3 -> 0 | I18: =F18*H18 -> 0 | M18: =J18*L18 -> 0 | Q18: =C18+F18+J18+N18 -> 2 | R18: =IF(Q18=0,"0.00",S18/Q18) -> 3.14 | S18: =E18+I18+M18+P18 -> 6.28 | T18: 2 | U18: =R18 -> 3.14 | V18: =T18*U18 -> 6.28 | W18: =Q18-T18 -> 0 | X18: =R18 -> 3.14 | Y18: =W18*X18 -> 0
A19: PRAWNS PEELED MEDIUM SIZE | B19: KGS | C19: 25 | D19: 8.0054881 | E19: =C19*D19 -> 200.1372 | H19: =G19/1.3 -> 0 | I19: =F19*H19 -> 0 | M19: =J19*L19 -> 0 | Q19: =C19+F19+J19+N19 -> 25 | R19: =IF(Q19=0,"0.00",S19/Q19) -> 8.0054881 | S19: =E19+I19+M19+P19 -> 200.1372 | T19: 12 | U19: =R19 -> 8.0054881 | V19: =T19*U19 -> 96.065857 | W19: =Q19-T19 -> 13 | X19: =R19 -> 8.0054881 | Y19: =W19*X19 -> 104.07135
A20: POMFRET BLACK | B20: KGS | C20: 27 | D20: 4.6343991 | E20: =C20*D20 -> 125.12878 | H20: =G20/1.3 -> 0 | I20: =F20*H20 -> 0 | M20: =J20*L20 -> 0 | Q20: =C20+F20+J20+N20 -> 27 | R20: =IF(Q20=0,"0.00",S20/Q20) -> 4.6343991 | S20: =E20+I20+M20+P20 -> 125.12878 | T20: 12 | U20: =R20 -> 4.6343991 | V20: =T20*U20 -> 55.612789 | W20: =Q20-T20 -> 15 | X20: =R20 -> 4.6343991 | Y20: =W20*X20 -> 69.515987
A21: POMFRET WHITE BLACK BIG SIZE | B21: KGS | C21: 18 | D21: 13.727818 | E21: =C21*D21 -> 247.10073 | H21: =G21/1.3 -> 0 | I21: =F21*H21 -> 0 | M21: =J21*L21 -> 0 | Q21: =C21+F21+J21+N21 -> 18 | R21: =IF(Q21=0,"0.00",S21/Q21) -> 13.727818 | S21: =E21+I21+M21+P21 -> 247.10073 | T21: 8 | U21: =R21 -> 13.727818 | V21: =T21*U21 -> 109.82255 | W21: =Q21-T21 -> 10 | X21: =R21 -> 13.727818 | Y21: =W21*X21 -> 137.27818
A22: KING FISH TENGGIRI | B22: KGS | C22: 0 | D22: 0.00 | E22: =C22*D22 -> 0 | H22: =G22/1.3 -> 0 | I22: =F22*H22 -> 0 | M22: =J22*L22 -> 0 | Q22: =C22+F22+J22+N22 -> 0 | R22: =IF(Q22=0,"0.00",S22/Q22) -> 0.00 | S22: =E22+I22+M22+P22 -> 0 | T22: 0 | U22: =R22 -> 0.00 | V22: =T22*U22 -> 0 | W22: =Q22-T22 -> 0 | X22: =R22 -> 0.00 | Y22: =W22*X22 -> 0
A23: LOPSTORS FISH | B23: KGS | C23: 0 | D23: 0.00 | E23: =C23*D23 -> 0 | H23: =G23/1.3 -> 0 | I23: =F23*H23 -> 0 | M23: =J23*L23 -> 0 | Q23: =C23+F23+J23+N23 -> 0 | R23: =IF(Q23=0,"0.00",S23/Q23) -> 0.00 | S23: =E23+I23+M23+P23 -> 0 | T23: 0 | U23: =R23 -> 0.00 | V23: =T23*U23 -> 0 | W23: =Q23-T23 -> 0 | X23: =R23 -> 0.00 | Y23: =W23*X23 -> 0
A24: RED SNAPPER FISH | B24: KGS | C24: 15 | D24: 7.0611452 | E24: =C24*D24 -> 105.91718 | H24: =G24/1.3 -> 0 | I24: =F24*H24 -> 0 | M24: =J24*L24 -> 0 | Q24: =C24+F24+J24+N24 -> 15 | R24: =IF(Q24=0,"0.00",S24/Q24) -> 7.0611452 | S24: =E24+I24+M24+P24 -> 105.91718 | T24: 7 | U24: =R24 -> 7.0611452 | V24: =T24*U24 -> 49.428016 | W24: =Q24-T24 -> 8 | X24: =R24 -> 7.0611452 | Y24: =W24*X24 -> 56.489161
A25: CRAB (BIG SIZE) | B25: KGS | C25: 20 | D25: 9.0454281 | E25: =C25*D25 -> 180.90856 | H25: =G25/1.3 -> 0 | I25: =F25*H25 -> 0 | M25: =J25*L25 -> 0 | Q25: =C25+F25+J25+N25 -> 20 | R25: =IF(Q25=0,"0.00",S25/Q25) -> 9.0454281 | S25: =E25+I25+M25+P25 -> 180.90856 | T25: 12 | U25: =R25 -> 9.0454281 | V25: =T25*U25 -> 108.54514 | W25: =Q25-T25 -> 8 | X25: =R25 -> 9.0454281 | Y25: =W25*X25 -> 72.363425
A26: MACKERAL | B26: KGS | C26: 11 | D26: 2.4740919 | E26: =C26*D26 -> 27.215011 | H26: =G26/1.3 -> 0 | I26: =F26*H26 -> 0 | M26: =J26*L26 -> 0 | Q26: =C26+F26+J26+N26 -> 11 | R26: =IF(Q26=0,"0.00",S26/Q26) -> 2.4740919 | S26: =E26+I26+M26+P26 -> 27.215011 | T26: 7 | U26: =R26 -> 2.4740919 | V26: =T26*U26 -> 17.318643 | W26: =Q26-T26 -> 4 | X26: =R26 -> 2.4740919 | Y26: =W26*X26 -> 9.8963675
A27: SALMON FISH | B27: KGS | C27: 20 | D27: 10.012861 | E27: =C27*D27 -> 200.25722 | H27: =G27/1.3 -> 0 | I27: =F27*H27 -> 0 | M27: =J27*L27 -> 0 | Q27: =C27+F27+J27+N27 -> 20 | R27: =IF(Q27=0,"0.00",S27/Q27) -> 10.012861 | S27: =E27+I27+M27+P27 -> 200.25722 | T27: 12 | U27: =R27 -> 10.012861 | V27: =T27*U27 -> 120.15433 | W27: =Q27-T27 -> 8 | X27: =R27 -> 10.012861 | Y27: =W27*X27 -> 80.102888
A28: CHICKEN BURGER PATTY | B28: PKT | C28: 11 | D28: 4.2190343 | E28: =C28*D28 -> 46.409377 | H28: =G28/1.3 -> 0 | I28: =F28*H28 -> 0 | M28: =J28*L28 -> 0 | Q28: =C28+F28+J28+N28 -> 11 | R28: =IF(Q28=0,"0.00",S28/Q28) -> 4.2190343 | S28: =E28+I28+M28+P28 -> 46.409377 | T28: 10 | U28: =R28 -> 4.2190343 | V28: =T28*U28 -> 42.190343 | W28: =Q28-T28 -> 1 | X28: =R28 -> 4.2190343 | Y28: =W28*X28 -> 4.2190343
A29: VEG BURGER PATTY | B29: PKT | C29: 45 | D29: 2.6153846 | E29: =C29*D29 -> 117.69231 | H29: =G29/1.3 -> 0 | I29: =F29*H29 -> 0 | M29: =J29*L29 -> 0 | Q29: =C29+F29+J29+N29 -> 45 | R29: =IF(Q29=0,"0.00",S29/Q29) -> 2.6153846 | S29: =E29+I29+M29+P29 -> 117.69231 | T29: 10 | U29: =R29 -> 2.6153846 | V29: =T29*U29 -> 26.153846 | W29: =Q29-T29 -> 35 | X29: =R29 -> 2.6153846 | Y29: =W29*X29 -> 91.538462
A30: BOONDI LADOO | B30: PKT | C30: 5 | D30: 4.0769231 | E30: =C30*D30 -> 20.384615 | H30: =G30/1.3 -> 0 | I30: =F30*H30 -> 0 | M30: =J30*L30 -> 0 | Q30: =C30+F30+J30+N30 -> 5 | R30: =IF(Q30=0,"0.00",S30/Q30) -> 4.0769231 | S30: =E30+I30+M30+P30 -> 20.384615 | T30: 1 | U30: =R30 -> 4.0769231 | V30: =T30*U30 -> 4.0769231 | W30: =Q30-T30 -> 4 | X30: =R30 -> 4.0769231 | Y30: =W30*X30 -> 16.307692
A31: BURGER BUN | B31: PKT | C31: 20 | D31: 2.0329028 | E31: =C31*D31 -> 40.658055 | H31: =G31/1.3 -> 0 | I31: =F31*H31 -> 0 | M31: =J31*L31 -> 0 | Q31: =C31+F31+J31+N31 -> 20 | R31: =IF(Q31=0,"0.00",S31/Q31) -> 2.0329028 | S31: =E31+I31+M31+P31 -> 40.658055 | T31: 10 | U31: =R31 -> 2.0329028 | V31: =T31*U31 -> 20.329028 | W31: =Q31-T31 -> 10 | X31: =R31 -> 2.0329028 | Y31: =W31*X31 -> 20.329028
A32: PIZZA BASE | B32: PCS | C32: 10 | D32: 0.96350688 | E32: =C32*D32 -> 9.6350688 | H32: =G32/1.3 -> 0 | I32: =F32*H32 -> 0 | M32: =J32*L32 -> 0 | Q32: =C32+F32+J32+N32 -> 10 | R32: =IF(Q32=0,"0.00",S32/Q32) -> 0.96350688 | S32: =E32+I32+M32+P32 -> 9.6350688 | T32: 5 | U32: =R32 -> 0.96350688 | V32: =T32*U32 -> 4.8175344 | W32: =Q32-T32 -> 5 | X32: =R32 -> 0.96350688 | Y32: =W32*X32 -> 4.8175344
A33: PAV BUN | B33: PKT | C33: 0 | D33: 0.00 | E33: =C33*D33 -> 0 | H33: =G33/1.3 -> 0 | I33: =F33*H33 -> 0 | M33: =J33*L33 -> 0 | Q33: =C33+F33+J33+N33 -> 0 | R33: =IF(Q33=0,"0.00",S33/Q33) -> 0.00 | S33: =E33+I33+M33+P33 -> 0 | T33: 0 | U33: =R33 -> 0.00 | V33: =T33*U33 -> 0 | W33: =Q33-T33 -> 0 | X33: =R33 -> 0.00 | Y33: =W33*X33 -> 0
A34: SPRING ROLL FORZEN | B34: PKT | C34: 20 | D34: 3.537981 | E34: =C34*D34 -> 70.75962 | H34: =G34/1.3 -> 0 | I34: =F34*H34 -> 0 | M34: =J34*L34 -> 0 | Q34: =C34+F34+J34+N34 -> 20 | R34: =IF(Q34=0,"0.00",S34/Q34) -> 3.537981 | S34: =E34+I34+M34+P34 -> 70.75962 | T34: 15 | U34: =R34 -> 3.537981 | V34: =T34*U34 -> 53.069715 | W34: =Q34-T34 -> 5 | X34: =R34 -> 3.537981 | Y34: =W34*X34 -> 17.689905
A35: SAMOSAA | B35: PKT | C35: 0 | D35: 0.00 | E35: =C35*D35 -> 0 | H35: =G35/1.3 -> 0 | I35: =F35*H35 -> 0 | M35: =J35*L35 -> 0 | Q35: =C35+F35+J35+N35 -> 0 | R35: =IF(Q35=0,"0.00",S35/Q35) -> 0.00 | S35: =E35+I35+M35+P35 -> 0 | T35: 0 | U35: =R35 -> 0.00 | V35: =T35*U35 -> 0 | W35: =Q35-T35 -> 0 | X35: =R35 -> 0.00 | Y35: =W35*X35 -> 0
A36: CHANNA MASALA (100GMS) | B36: PKT | C36: 10 | D36: 1.3568173 | E36: =C36*D36 -> 13.568173 | H36: =G36/1.3 -> 0 | I36: =F36*H36 -> 0 | M36: =J36*L36 -> 0 | Q36: =C36+F36+J36+N36 -> 10 | R36: =IF(Q36=0,"0.00",S36/Q36) -> 1.3568173 | S36: =E36+I36+M36+P36 -> 13.568173 | T36: 5 | U36: =R36 -> 1.3568173 | V36: =T36*U36 -> 6.7840865 | W36: =Q36-T36 -> 5 | X36: =R36 -> 1.3568173 | Y36: =W36*X36 -> 6.7840865
A37: BIRYANI MASALA (100 GMS) | B37: PKT | C37: 30 | D37: 1.2142033 | E37: =C37*D37 -> 36.4261 | H37: =G37/1.3 -> 0 | I37: =F37*H37 -> 0 | M37: =J37*L37 -> 0 | Q37: =C37+F37+J37+N37 -> 30 | R37: =IF(Q37=0,"0.00",S37/Q37) -> 1.2142033 | S37: =E37+I37+M37+P37 -> 36.4261 | T37: 18 | U37: =R37 -> 1.2142033 | V37: =T37*U37 -> 21.85566 | W37: =Q37-T37 -> 12 | X37: =R37 -> 1.2142033 | Y37: =W37*X37 -> 14.57044
A38: PAV BHAJI MASALA(100 GMS) | B38: PKT | C38: 5 | D38: 1.2995079 | E38: =C38*D38 -> 6.4975394 | H38: =G38/1.3 -> 0 | I38: =F38*H38 -> 0 | M38: =J38*L38 -> 0 | Q38: =C38+F38+J38+N38 -> 5 | R38: =IF(Q38=0,"0.00",S38/Q38) -> 1.2995079 | S38: =E38+I38+M38+P38 -> 6.4975394 | T38: 5 | U38: =R38 -> 1.2995079 | V38: =T38*U38 -> 6.4975394 | W38: =Q38-T38 -> 0 | X38: =R38 -> 1.2995079 | Y38: =W38*X38 -> 0
A39: SAMBHAR MASALA(100 GMS) | B39: PKT | C39: 30 | D39: 0.87687677 | E39: =C39*D39 -> 26.306303 | H39: =G39/1.3 -> 0 | I39: =F39*H39 -> 0 | M39: =J39*L39 -> 0 | Q39: =C39+F39+J39+N39 -> 30 | R39: =IF(Q39=0,"0.00",S39/Q39) -> 0.87687677 | S39: =E39+I39+M39+P39 -> 26.306303 | T39: 15 | U39: =R39 -> 0.87687677 | V39: =T39*U39 -> 13.153151 | W39: =Q39-T39 -> 15 | X39: =R39 -> 0.87687677 | Y39: =W39*X39 -> 13.153151
A40: CHICKEN MASALA(100 GMS) | B40: PKT | C40: 35 | D40: 0.92065667 | E40: =C40*D40 -> 32.222983 | H40: =G40/1.3 -> 0 | I40: =F40*H40 -> 0 | M40: =J40*L40 -> 0 | Q40: =C40+F40+J40+N40 -> 35 | R40: =IF(Q40=0,"0.00",S40/Q40) -> 0.92065667 | S40: =E40+I40+M40+P40 -> 32.222983 | T40: 15 | U40: =R40 -> 0.92065667 | V40: =T40*U40 -> 13.80985 | W40: =Q40-T40 -> 20 | X40: =R40 -> 0.92065667 | Y40: =W40*X40 -> 18.413133
A41: KITCHEN KING MASALA (100GHMS) | B41: PKT | C41: 12 | D41: 1.3477376 | E41: =C41*D41 -> 16.172851 | H41: =G41/1.3 -> 0 | I41: =F41*H41 -> 0 | M41: =J41*L41 -> 0 | Q41: =C41+F41+J41+N41 -> 12 | R41: =IF(Q41=0,"0.00",S41/Q41) -> 1.3477376 | S41: =E41+I41+M41+P41 -> 16.172851 | T41: 6 | U41: =R41 -> 1.3477376 | V41: =T41*U41 -> 8.0864253 | W41: =Q41-T41 -> 6 | X41: =R41 -> 1.3477376 | Y41: =W41*X41 -> 8.0864253
...

Sheet OUTPORT MESSING
A1: MT ALMA
A2: STATEMENT OF MAN DAYS
A3: OUTPORT MESSING
B4: ='Provisions Covering Sheet'!J4 -> 46021
A5: No. | B5: Ranks | C5: From | D5: To | E5: No. of persons | F5: No. of days | G5: Number of meals | H5: Total Man days | I5: USD
A7: OUT PORT EXPENSES
A8: 1 | B8: 2 Surveyor and 1 sampling person at load port TB Indonesia | C8: 06.12.2025 | D8: 07.12.2025 | E8: 3 | F8: 1 | G8: Manually enter | I8: =H8*'Provisions Covering Sheet'!J23 -> 0
A9: 2 | B9: 1 Agent at disport | C9: 18.12.2025 | D9: 20.12.2025 | E9: 1 | F9: 3 | G9: Manually enter | I9: =H9*'Provisions Covering Sheet'!J23 -> 0
I10: =H10*'Provisions Covering Sheet'!J23 -> 0
I11: =H11*'Provisions Covering Sheet'!J23 -> 0
I12: =H12*'Provisions Covering Sheet'!J23 -> 0
I13: =H13*'Provisions Covering Sheet'!J23 -> 0
C16: Total Mandays: | H16: =SUM(H8:H15) -> 0 | I16: =SUM(I8:I15) -> 0
B18: CONSUMPTION | D18: TOTAL | I18: =I16 -> 0
E25: ='Provisions Covering Sheet'!L31 -> Master name
F26: ='Provisions Covering Sheet'!L32 -> Vessel Name

Sheet Spoiled Items 
A2: MT ALMA | E2: ='Provisions Covering Sheet'!J4 -> 46021
A6: ITEM | B6: UNIT | C6: ITEMS DAMAGED DURING BLACKOUT
C7: WEIGHT | D7: UNIT | E7: TOTAL
D8: COST
B9: KG | E9: =C9*D9*0.8 -> 0
B10: KG | E10: =C10*D10*0.8 -> 0
B11: KG | E11: =C11*D11*0.8 -> 0
B12: KG | E12: =C12*D12*0.8 -> 0
A13: TOTAL | E13: =SUM(E9:E12) -> 0
B15: KG | E15: =C15*D15*0.8 -> 0
B16: KG | E16: =C16*D16*0.8 -> 0
B17: KG | E17: =C17*D17*0.8 -> 0
A18: TOTAL | E18: =SUM(E15:E17) -> 0
A20: T O T A L S | E20: =E13+E18 -> 0
C26: ='Provisions Covering Sheet'!L31 -> Master name
C27: ='Provisions Covering Sheet'!L32:L32 -> Vessel Name
