Workbook

Sheet 2AL
A4: ALLOTMENT 2
A6: No | B6: Name | C6: Rank | D6: Month / Year | E6: Amount USD
A7: 1 | B7: =#REF! -> #REF! | C7: =#REF! -> #REF!
A8: 2 | B8: =#REF! -> #REF! | C8: =#REF! -> #REF!
A9: 3 | B9: =#REF! -> #REF! | C9: =#REF! -> #REF!
A10: 4 | B10: =#REF! -> #REF! | C10: =#REF! -> #REF!
A11: 5 | B11: =#REF! -> #REF! | C11: =#REF! -> #REF!
A12: 6 | B12: =#REF! -> #REF! | C12: =#REF! -> #REF!
A13: 7 | B13: =#REF! -> #REF! | C13: =#REF! -> #REF!
A14: 8 | B14: =#REF! -> #REF! | C14: =#REF! -> #REF!
A15: 9 | B15: =#REF! -> #REF! | C15: =#REF! -> #REF!
A16: 10 | B16: =#REF! -> #REF! | C16: =#REF! -> #REF!
A17: 11 | B17: =#REF! -> #REF! | C17: =#REF! -> #REF!
A18: 12 | B18: =#REF! -> #REF! | C18: =#REF! -> #REF!
A19: 13 | B19: =#REF! -> #REF! | C19: =#REF! -> #REF!
... A26: 20 | B26: =#REF! -> #REF! | C26: =#REF! -> #REF!
A27: 31
D28: Total USD | E28: =SUM(E7:E27) -> 0
C33: Master | D33: =#REF! -> #REF!

Sheet 1AD
E2: =#REF! -> #REF!
A4: CASH ADVANCE 1
A6: No | B6: Name | C6: Rank | D6: Month / Year | E6: Amount USD
A7: 1 | B7: =#REF! -> #REF! | C7: =#REF! -> #REF! | D7: =#REF! -> #REF!
A8: 2 | B8: =#REF! -> #REF! | C8: =#REF! -> #REF! | D8: =#REF! -> #REF!
A9: 3 | B9: =#REF! -> #REF! | C9: =#REF! -> #REF! | D9: =#REF! -> #REF!
A10: 4 | B10: =#REF! -> #REF! | C10: =#REF! -> #REF! | D10: =#REF! -> #REF!
A11: 5 | B11: =#REF! -> #REF! | C11: =#REF! -> #REF! | D11: =#REF! -> #REF!
A12: 6 | B12: =#REF! -> #REF! | C12: =#REF! -> #REF! | D12: =#REF! -> #REF!
A13: 7 | B13: =#REF! -> #REF! | C13: =#REF! -> #REF! | D13: =#REF! -> #REF!
A14: 8 | B14: =#REF! -> #REF! | C14: =#REF! -> #REF! | D14: =#REF! -> #REF!
A15: 9 | B15: =#REF! -> #REF! | C15: =#REF! -> #REF! | D15: =#REF! -> #REF!
A16: 10 | B16: =#REF! -> #REF! | C16: =#REF! -> #REF! | D16: =#REF! -> #REF!
A17: 11 | B17: =#REF! -> #REF! | C17: =#REF! -> #REF! | D17: =#REF! -> #REF!
A18: 12 | B18: =#REF! -> #REF! | C18: =#REF! -> #REF! | D18: =#REF! -> #REF!
... A20: 14 | B20: =#REF! -> #REF! | C20: =#REF! -> #REF! | D20: =#REF! -> #REF!
A21: 15 | B21: =#REF! -> #REF! | C21: =#REF! -> #REF! | D21: =IF(B21="","",#REF!) -> #REF!
A22: 16 | B22: =#REF! -> #REF! | C22: =#REF! -> #REF! | D22: =IF(B22="","",#REF!) -> #REF!
A23: 17 | B23: =#REF! -> #REF! | C23: =#REF! -> #REF! | D23: =IF(B23="","",#REF!) -> #REF!
A24: 18 | B24: =#REF! -> #REF! | C24: =#REF! -> #REF! | D24: =IF(B24="","",#REF!) -> #REF!
A25: 19 | B25: =#REF! -> #REF! | C25: =#REF! -> #REF! | D25: =IF(B25="","",#REF!) -> #REF!
A26: 20 | B26: =#REF! -> #REF! | C26: =#REF! -> #REF!
D27: Total USD | E27: =SUM(E7:E26) -> 0
C32: =#REF! -> #REF!
C34: Master | D34: =#REF! -> #REF!

Sheet 3AD
A4: CASH ADVANCE 3
A6: No | B6: Name | C6: Rank | D6: Month / Year | E6: Amount USD
A7: =#REF! -> #REF! | B7: =#REF! -> #REF! | C7: =#REF! -> #REF! | D7: =IF(B7="","",#REF!) -> #REF! | J7: =I7*$I$6 -> 0
A8: =#REF! -> #REF! | B8: =#REF! -> #REF! | C8: =#REF! -> #REF! | D8: =IF(B8="","",#REF!) -> #REF! | J8: =I8*$I$6 -> 0
A9: =#REF! -> #REF! | B9: =#REF! -> #REF! | C9: =#REF! -> #REF! | D9: =IF(B9="","",#REF!) -> #REF! | J9: =I9*$I$6 -> 0 | L9: =K9*$K$6 -> 0
A10: =#REF! -> #REF! | B10: =#REF! -> #REF! | C10: =#REF! -> #REF! | D10: =IF(B10="","",#REF!) -> #REF! | J10: =I10*$I$6 -> 0 | L10: =K10*$K$6 -> 0
A11: =#REF! -> #REF! | B11: =#REF! -> #REF! | C11: =#REF! -> #REF! | D11: =IF(B11="","",#REF!) -> #REF! | J11: =I11*$I$6 -> 0 | L11: =K11*$K$6 -> 0
A12: =#REF! -> #REF! | B12: =#REF! -> #REF! | C12: =#REF! -> #REF! | D12: =IF(B12="","",#REF!) -> #REF! | J12: =I12*$I$6 -> 0 | L12: =K12*$K$6 -> 0
A13: =#REF! -> #REF! | B13: =#REF! -> #REF! | C13: =#REF! -> #REF! | D13: =IF(B13="","",#REF!) -> #REF! | J13: =I13*$I$6 -> 0 | L13: =K13*$K$6 -> 0
A14: =#REF! -> #REF! | B14: =#REF! -> #REF! | C14: =#REF! -> #REF! | D14: =IF(B14="","",#REF!) -> #REF! | J14: =I14*$I$6 -> 0 | L14: =K14*$K$6 -> 0
A15: =#REF! -> #REF! | B15: =#REF! -> #REF! | C15: =#REF! -> #REF! | D15: =IF(B15="","",#REF!) -> #REF! | J15: =I15*$I$6 -> 0 | L15: =K15*$K$6 -> 0
A16: =#REF! -> #REF! | B16: =#REF! -> #REF! | C16: =#REF! -> #REF! | D16: =IF(B16="","",#REF!) -> #REF! | J16: =I16*$I$6 -> 0 | L16: =K16*$K$6 -> 0
A17: =#REF! -> #REF! | B17: =#REF! -> #REF! | C17: =#REF! -> #REF! | D17: =IF(B17="","",#REF!) -> #REF! | J17: =I17*$I$6 -> 0 | L17: =K17*$K$6 -> 0
A18: =#REF! -> #REF! | B18: =#REF! -> #REF! | C18: =#REF! -> #REF! | D18: =IF(B18="","",#REF!) -> #REF! | J18: =I18*$I$6 -> 0 | L18: =K18*$K$6 -> 0
A19: =#REF! -> #REF! | B19: =#REF! -> #REF! | C19: =#REF! -> #REF! | D19: =IF(B19="","",#REF!) -> #REF! | J19: =I19*$I$6 -> 0 | L19: =K19*$K$6 -> 0
A20: =#REF! -> #REF! | B20: =#REF! -> #REF! | C20: =#REF! -> #REF! | D20: =IF(B20="","",#REF!) -> #REF! | J20: =I20*$I$6 -> 0 | L20: =K20*$K$6 -> 0
A21: 15 | B21: =#REF! -> #REF! | C21: =#REF! -> #REF! | D21: =IF(B21="","",#REF!) -> #REF! | J21: =I21*$I$6 -> 0 | L21: =K21*$K$6 -> 0
A22: =#REF! -> #REF! | B22: =#REF! -> #REF! | C22: =#REF! -> #REF! | D22: =IF(B22="","",#REF!) -> #REF! | J22: =I22*$I$6 -> 0 | L22: =K22*$K$6 -> 0
A23: 17 | B23: =#REF! -> #REF! | C23: =#REF! -> #REF! | D23: =IF(B23="","",#REF!) -> #REF! | L23: =K23*$K$6 -> 0
A24: =#REF! -> #REF! | B24: =#REF! -> #REF! | C24: =#REF! -> #REF! | D24: =IF(B24="","",#REF!) -> #REF! | L24: =K24*$K$6 -> 0
A25: =#REF! -> #REF! | B25: =#REF! -> #REF! | C25: =#REF! -> #REF! | D25: =IF(B25="","",#REF!) -> #REF! | L25: =K25*$K$6 -> 0
A26: =#REF! -> #REF! | B26: =#REF! -> #REF! | C26: =#REF! -> #REF!
D27: Total USD | E27: =SUM(E7:E26) -> 0
C34: Master | D34: =#REF! -> #REF!

Sheet Bond
A1: Bonded Stores Account
A3: Vessel Name : xxxx | H3: Date: | I3: 46022
A5: No. | B5: Items | D5: Units | E5: Qty Received | F5: Qty Consumed | G5: Price USD | H5: Total Received | I5: Expiry Date
A7: Balance B/Ffrom Last month: NOV 25
B8: Items | E8: Numbers | G8: Unit price | H8: Total | I8: Expiry details
A9: 1 | B9: Marlboro Gold Cigarattes | D9: carton | E9: 25 | G9: 24.09 | H9: =G9*E9 -> 602.25 | I9: NA
A10: 2 | B10: Manchester Light Cigarattes / New | D10: carton | E10: 70 | G10: 6.92 | H10: =G10*E10 -> 484.4 | I10: NA
A11: 3 | B11: Almonds | D11: Tin | E11: 16 | G11: 4.615 | H11: =G11*E11 -> 73.84 | I11: 46066
A12: 4 | B12: Peanuts (150 gm) | D12: Tin | E12: 18 | G12: 2.15 | H12: =G12*E12 -> 38.7 | I12: 46016
A13: 5 | B13: Haldiram Bhujia Sev 150 gm | D13: Pkt | E13: 0 | G13: 0 | H13: =G13*E13 -> 0 | I13: NA
A14: 6 | B14: Tooth Brush | D14: Pcs | E14: 5 | G14: 2.71 | H14: =G14*E14 -> 13.55 | I14: NA
A15: 7 | B15: Tooth Paste | D15: Pkt | E15: 4 | G15: 3.739 | H15: =G15*E15 -> 14.956 | I15: 46417
A16: 8 | B16: Head & Shoulder Shampoo | D16: Btl | E16: 0 | G16: 0 | H16: =G16*E16 -> 0 | I16: NA
A17: 9 | B17: Listerine 1 Ltr | D17: Btl | E17: 2 | G17: 6.2 | H17: =G17*E17 -> 12.4 | I17: 46476
A18: 10 | B18: Marlboro Gold Cigarattes / old | D18: carton | E18: 24 | G18: 25.56 | H18: =G18*E18 -> 613.44 | I18: NA
A19: 11 | B19: Drinking Water 500ml | D19: case | E19: 4 | G19: 3.359 | H19: =G19*E19 -> 13.436 | I19: NA
A20: 12 | B20: Cashew nuts (130 gm) | D20: Tin | E20: 39 | G20: 6.03 | H20: =G20*E20 -> 235.17 | I20: 46100
A21: 13 | B21: Chocolate Mars (51 G) | D21: Pcs | E21: 42 | G21: 1.3 | H21: =G21*E21 -> 54.6 | I21: 46005
A22: 14 | B22: Chocolate Snickers (45 G) | D22: Pcs | E22: 26 | G22: 1.3 | H22: =G22*E22 -> 33.8 | I22: 46057
A23: 15 | B23: Coke | D23: Case | E23: 2 | G23: 13.62 | H23: =G23*E23 -> 27.24 | I23: 46067
A24: 16 | B24: Sprite | D24: Case | E24: 3 | G24: 15.07 | H24: =G24*E24 -> 45.21 | I24: 46151
A25: 17 | B25: Fanta | D25: Case | E25: 4 | G25: 8.31 | H25: =G25*E25 -> 33.24 | I25: 46086
A26: 18 | B26: Pistachio (1 KG) | D26: Pkt | E26: 1 | G26: 25.1 | H26: =G26*E26 -> 25.1 | I26: 46265
A27: 19 | B27: Lays (170 gm) | D27: Pkt | E27: 0 | G27: 0 | H27: =G27*E27 -> 0 | I27: 45990
A28: 20 | B28: Doritos (190 G) | D28: Pkt | E28: 0 | G28: 0 | H28: =G28*E28 -> 0 | I28: 45963
A29: 21 | B29: Pringles Orignal (134 g) | D29: Tub | E29: 13 | G29: 3.72 | H29: =G29*E29 -> 48.36 | I29: 46085
A30: 22 | B30: Pringles Sour Cream & Onion (134 g) | D30: Tub | E30: 15 | G30: 3.72 | H30: =G30*E30 -> 55.8 | I30: 46155
A31: Total: | H31: =SUM(H9:H30) -> 2425.492
B32: BOND RECEIVED DURING THE MONTH OF DEC 2025
A33: 1 | B33: Marlboro Gold Cigarattes | D33: carton | E33: 0 | G33: 24.09 | H33: =E33*G33 -> 0
A34: 2 | B34: Manchester Light Cigarattes | D34: carton | E34: 0 | G34: 6.92 | H34: =E34*G34 -> 0
A35: 3 | B35: Drinking Water 500ml | D35: case | E35: 0 | G35: 3.359 | H35: =E35*G35 -> 0
A36: Total: | H36: =SUM(H33:H35) -> 0
A39: Representation expences DEC 2025
A41: S.NO | B41: ITEM | D41: UNIT | E41: REP. | F41: QTY | G41: PRICE | I41: TOTAL
A42: 1 | B42: Marlboro Gold Cigarattes / old | E42: Customs, Immigrations, Agent, Harbour Master(TANJUNG BERAKIT) | F42: 4 | G42: 25.56 | I42: =F42*G42 -> 102.24
A43: 2 | B43: Manchester Light Cigarattes / New | E43: Customs, Immigrations, Agent, Harbour Master(TANJUNG BERAKIT) | F43: 5 | G43: 6.92 | I43: =F43*G43 -> 34.6
A44: 3 | B44: Manchester Light Cigarattes / New | E44: 2 SayBolt Surveyors & 1 Sampling Person(TANJUNG BERAKIT) | F44: 3 | G44: 6.92 | I44: =F44*G44 -> 20.76
A45: 4 | B45: Coke | E45: Customs, Immigrations, Agent, Harbour Master(TANJUNG BERAKIT) | F45: 1 | G45: 13.62 | I45: =F45*G45 -> 13.62
A46: 5 | B46: Chocolate Snickers (45 G) | E46: Customs, Immigrations, Agent, Harbour Master(TANJUNG BERAKIT) | F46: 2 | G46: 1.3 | I46: =F46*G46 -> 2.6
...

Sheet Slopchest
A1: Slopchest Deductions
A3: Vessel: | C3: M.T ALMA | X3: DEC-2025
A4: No | B4: Name | C4: Rank | Z4: Total Deductions | AA4: Signature
D5: =Bond!B62 -> Marlboro Gold Cigarattes / New | E5: =Bond!B63 -> Manchester Light Cigarattes / New | F5: =Bond!B11 -> Almonds | G5: =Bond!B12 -> Peanuts (150 gm) | H5: =Bond!B13 -> Haldiram Bhujia Sev 150 gm | I5: =Bond!B14 -> Tooth Brush | J5: =Bond!B15 -> Tooth Paste | K5: =Bond!B16 -> Head & Shoulder Shampoo | L5: =Bond!B17 -> Listerine 1 Ltr | M5: =Bond!B18 -> Marlboro Gold Cigarattes / old | N5: =Bond!B70 -> Drinking Water 500ml | O5: =Bond!B20 -> Cashew nuts (130 gm) | P5: =Bond!B21 -> Chocolate Mars (51 G) | Q5: =Bond!B22 -> Chocolate Snickers (45 G) | R5: =Bond!B23 -> Coke | S5: =Bond!B24 -> Sprite | T5: =Bond!B25 -> Fanta | U5: =Bond!B26 -> Pistachio (1 KG) | V5: =Bond!B27 -> Lays (170 gm) | W5: =Bond!B28 -> Doritos (190 G) | X5: =Bond!B29 -> Pringles Orignal (134 g) | Y5: =Bond!B30 -> Pringles Sour Cream & Onion (134 g)
D6: =Bond!G62 -> 24.09 | E6: =Bond!G63 -> 6.92 | F6: =Bond!G11 -> 4.615 | G6: =Bond!G12 -> 2.15 | H6: =Bond!G13 -> 0 | I6: =Bond!G14 -> 2.71 | J6: =Bond!G15 -> 3.739 | K6: =Bond!G16 -> 0 | L6: =Bond!G17 -> 6.2 | M6: =Bond!G18 -> 25.56 | N6: =Bond!G70 -> 3.359 | O6: =Bond!G20 -> 6.03 | P6: =Bond!G21 -> 1.3 | Q6: =Bond!G22 -> 1.3 | R6: =Bond!G23 -> 13.62 | S6: =Bond!G24 -> 15.07 | T6: =Bond!G25 -> 8.31 | U6: =Bond!G26 -> 25.1 | V6: =Bond!G27 -> 0 | W6: =Bond!G28 -> 0 | X6: =Bond!G29 -> 3.72 | Y6: =Bond!G30 -> 3.72
A7: 1 | C7: Master | Z7: =(D6*D7)+(E6*E7)+(F6*F7)+(G6*G7)+(H6*H7)+(I6*I7)+(J6*J7)+(K6*K7)+(L6*L7)+(M6*M7)+(N6*N7)+(O6*O7)+(P6*P7)+(Q6*Q7)+(R6*R7)+(S6*S7)+(T6*T7)+(U6*U7)+(V6*V7)+(W6*W7)+(X6*X7)+(Y6*Y7) -> 0
A8: 2 | C8: Chief Officer | G8: 0 | X8: 0 | Y8: 0 | Z8: =(D6*D8)+(E6*E8)+(F6*F8)+(G6*G8)+(H6*H8)+(I6*I8)+(J6*J8)+(K6*K8)+(L6*L8)+(M6*M8)+(N6*N8)+(O6*O8)+(P6*P8)+(Q6*Q8)+(R6*R8)+(S6*S8)+(T6*T8)+(U6*U8)+(V6*V8)+(W6*W8)+(X6*X8)+(Y6*Y8) -> 0
A9: 3 | C9: ADD'L Chief officer | Z9: =(D6*D9)+(E6*E9)+(F6*F9)+(G6*G9)+(H6*H9)+(I6*I9)+(J6*J9)+(K6*K9)+(L6*L9)+(M6*M9)+(N6*N9)+(O6*O9)+(P6*P9)+(Q6*Q9)+(R6*R9)+(S6*S9)+(T6*T9)+(U6*U9)+(V6*V9)+(W6*W9)+(X6*X9)+(Y6*Y9) -> 0
A10: 4 | C10: 2ND Officer | Z10: =(D6*D10)+(E6*E10)+(F6*F10)+(G6*G10)+(H6*H10)+(I6*I10)+(J6*J10)+(K6*K10)+(L6*L10)+(M6*M10)+(N6*N10)+(O6*O10)+(P6*P10)+(Q6*Q10)+(R6*R10)+(S6*S10)+(T6*T10)+(U6*U10)+(V6*V10)+(W6*W10)+(X6*X10)+(Y6*Y10) -> 0
A11: 5 | C11: Deck Cadet | Z11: =(D6*D11)+(E6*E11)+(F6*F11)+(G6*G11)+(H6*H11)+(I6*I11)+(J6*J11)+(K6*K11)+(L6*L11)+(M6*M11)+(N6*N11)+(O6*O11)+(P6*P11)+(Q6*Q11)+(R6*R11)+(S6*S11)+(T6*T11)+(U6*U11)+(V6*V11)+(W6*W11)+(X6*X11)+(Y6*Y11) -> 0
A12: 6 | C12: Ch.Engineer | Z12: =(D6*D12)+(E6*E12)+(F6*F12)+(G6*G12)+(H6*H12)+(I6*I12)+(J6*J12)+(K6*K12)+(L6*L12)+(M6*M12)+(N6*N12)+(O6*O12)+(P6*P12)+(Q6*Q12)+(R6*R12)+(S6*S12)+(T6*T12)+(U6*U12)+(V6*V12)+(W6*W12)+(X6*X12)+(Y6*Y12) -> 0
A13: 7 | C13: 2nd Engineer | G13: 0 | O13: 0 | R13: 0 | Z13: =(D6*D13)+(E6*E13)+(F6*F13)+(G6*G13)+(H6*H13)+(I6*I13)+(J6*J13)+(K6*K13)+(L6*L13)+(M6*M13)+(N6*N13)+(O6*O13)+(P6*P13)+(Q6*Q13)+(R6*R13)+(S6*S13)+(T6*T13)+(U6*U13)+(V6*V13)+0+0+(W6*W13)+(X6*X13)+(Y13*Y6) -> 0
A14: 8 | C14: 3rd.Engineer | E14: 1 | Y14: 1 | Z14: =(D6*D14)+(E6*E14)+(F6*F14)+(G6*G14)+(H6*H14)+(I6*I14)+(J6*J14)+(K6*K14)+(L6*L14)+(M6*M14)+(N6*N14)+(O6*O14)+(P6*P14)+(Q6*Q14)+(R6*R14)+(S6*S14)+(T6*T14)+(U6*U14)+(V6*V14)+0+0+(W6*W14)+(X6*X14)+(Y14*Y6) -> 10.64
A15: 9 | C15: 4th Engineer | Z15: =(D6*D15)+(E6*E15)+(F6*F15)+(G6*G15)+(H6*H15)+(I6*I15)+(J6*J15)+(K6*K15)+(L6*L15)+(M6*M15)+(N6*N15)+(O6*O15)+(P6*P15)+(Q6*Q15)+(R6*R15)+(S6*S15)+(T6*T15)+(U6*U15)+(V6*V15)+0+0+(W6*W15)+(X6*X15)+(Y15*Y6) -> 0
A16: 10 | C16: ETO | Z16: =(D6*D16)+(E6*E16)+(F6*F16)+(G6*G16)+(H6*H16)+(I6*I16)+(J6*J16)+(K6*K16)+(L6*L16)+(M6*M16)+(N6*N16)+(O6*O16)+(P6*P16)+(Q6*Q16)+(R6*R16)+(S6*S16)+(T6*T16)+(U6*U16)+(V6*V16)+0+0+(W6*W16)+(X6*X16)+(Y16*Y6) -> 0
A17: 11 | C17: TME | Z17: =(D6*D17)+(E6*E17)+(F6*F17)+(G6*G17)+(H6*H17)+(I6*I17)+(J6*J17)+(K6*K17)+(L6*L17)+(M6*M17)+(N6*N17)+(O6*O17)+(P6*P17)+(Q6*Q17)+(R6*R17)+(S6*S17)+(T6*T17)+(U6*U17)+(V6*V17)+0+0+(W6*W17)+(X6*X17)+(Y17*Y6) -> 0
A18: 12 | C18: Pumpman | Z18: =(D6*D18)+(E6*E18)+(F6*F18)+(G6*G18)+(H6*H18)+(I6*I18)+(J6*J18)+(K6*K18)+(L6*L18)+(M6*M18)+(N6*N18)+(O6*O18)+(P6*P18)+(Q6*Q18)+(R6*R18)+(S6*S18)+(T6*T18)+(U6*U18)+(V6*V18)+0+0+(W6*W18)+(X6*X18)+(Y18*Y6) -> 0
A19: 13 | C19: BOSUN | Z19: =(D6*D19)+(E6*E19)+(F6*F19)+(G6*G19)+(H6*H19)+(I6*I19)+(J6*J19)+(K6*K19)+(L6*L19)+(M6*M19)+(N6*N19)+(O6*O19)+(P6*P19)+(Q6*Q19)+(R6*R19)+(S6*S19)+(T6*T19)+(U6*U19)+(V6*V19)+0+0+(W6*W19)+(X6*X19)+(Y19*Y6) -> 0
A20: 14 | C20: AB 1 | Z20: =(D6*D20)+(E6*E20)+(F6*F20)+(G6*G20)+(H6*H20)+(I6*I20)+(J6*J20)+(K6*K20)+(L6*L20)+(M6*M20)+(N6*N20)+(O6*O20)+(P6*P20)+(Q6*Q20)+(R6*R20)+(S6*S20)+(T6*T20)+(U6*U20)+(V6*V20)+0+0+(W6*W20)+(X6*X20)+(Y20*Y6) -> 0
A21: 15 | C21: AB 2 | Z21: =(D6*D21)+(E6*E21)+(F6*F21)+(G6*G21)+(H6*H21)+(I6*I21)+(J6*J21)+(K6*K21)+(L6*L21)+(M6*M21)+(N6*N21)+(O6*O21)+(P6*P21)+(Q6*Q21)+(R6*R21)+(S6*S21)+(T6*T21)+(U6*U21)+(V6*V21)+0+0+(W6*W21)+(X6*X21)+(Y21*Y6) -> 0
A22: 16 | C22: AB 3 | Z22: =(D6*D22)+(E6*E22)+(F6*F22)+(G6*G22)+(H6*H22)+(I6*I22)+(J6*J22)+(K6*K22)+(L6*L22)+(M6*M22)+(N6*N22)+(O6*O22)+(P6*P22)+(Q6*Q22)+(R6*R22)+(S6*S22)+(T6*T22)+(U6*U22)+(V6*V22)+0+0+(W6*W22)+(X6*X22)+(Y22*Y6) -> 0
A23: 17 | C23: OS1 | Z23: =(D6*D23)+(E6*E23)+(F6*F23)+(G6*G23)+(H6*H23)+(I6*I23)+(J6*J23)+(K6*K23)+(L6*L23)+(M6*M23)+(N6*N23)+(O6*O23)+(P6*P23)+(Q6*Q23)+(R6*R23)+(S6*S23)+(T6*T23)+(U6*U23)+(V6*V23)+0+0+(W6*W23)+(X6*X23)+(Y23*Y6) -> 0
A24: 18 | C24: OS2 | Z24: =(D6*D24)+(E6*E24)+(F6*F24)+(G6*G24)+(H6*H24)+(I6*I24)+(J6*J24)+(K6*K24)+(L6*L24)+(M6*M24)+(N6*N24)+(O6*O24)+(P6*P24)+(Q6*Q24)+(R6*R24)+(S6*S24)+(T6*T24)+(U6*U24)+(V6*V24)+0+0+(W6*W24)+(X6*X24)+(Y24*Y6) -> 0
A25: 19 | C25: Oiler 1 | Z25: =(D6*D25)+(E6*E25)+(F6*F25)+(G6*G25)+(H6*H25)+(I6*I25)+(J6*J25)+(K6*K25)+(L6*L25)+(M6*M25)+(N6*N25)+(O6*O25)+(P6*P25)+(Q6*Q25)+(R6*R25)+(S6*S25)+(T6*T25)+(U6*U25)+(V6*V25)+0+0+(W6*W25)+(X6*X25)+(Y25*Y6) -> 0
A26: 20 | C26: Oiler 2 | Z26: =(D6*D26)+(E6*E26)+(F6*F26)+(G6*G26)+(H6*H26)+(I6*I26)+(J6*J26)+(K6*K26)+(L6*L26)+(M6*M26)+(N6*N26)+(O6*O26)+(P6*P26)+(Q6*Q26)+(R6*R26)+(S6*S26)+(T6*T26)+(U6*U26)+(V6*V26)+0+0+(W6*W26)+(X6*X26)+(Y26*Y6) -> 0
A27: 21 | C27: Oiler 3 | Z27: =(D6*D27)+(E6*E27)+(F6*F27)+(G6*G27)+(H6*H27)+(I6*I27)+(J6*J27)+(K6*K27)+(L6*L27)+(M6*M27)+(N6*N27)+(O6*O27)+(P6*P27)+(Q6*Q27)+(R6*R27)+(S6*S27)+(T6*T27)+(U6*U27)+(V6*V27)+0+0+(W6*W27)+(X6*X27)+(Y27*Y6) -> 0
A28: 22 | C28: Fitter | Z28: =(D6*D28)+(E6*E28)+(F6*F28)+(G6*G28)+(H6*H28)+(I6*I28)+(J6*J28)+(K6*K28)+(L6*L28)+(M6*M28)+(N6*N28)+(O6*O28)+(P6*P28)+(Q6*Q28)+(R6*R28)+(S6*S28)+(T6*T28)+(U6*U28)+(V6*V28)+0+0+(W6*W28)+(X6*X28)+(Y28*Y6) -> 0
A29: 23 | C29: Ch Cook | E29: 0 | Z29: =(D6*D29)+(E6*E29)+(F6*F29)+(G6*G29)+(H6*H29)+(I6*I29)+(J6*J29)+(K6*K29)+(L6*L29)+(M6*M29)+(N6*N29)+(O6*O29)+(P6*P29)+(Q6*Q29)+(R6*R29)+(S6*S29)+(T6*T29)+(U6*U29)+(V6*V29)+0+0+(W6*W29)+(X6*X29)+(Y29*Y6) -> 0
A30: 24 | C30: TRAINEE GS | Z30: =(D6*D30)+(E6*E30)+(F6*F30)+(G6*G30)+(H6*H30)+(I6*I30)+(J6*J30)+(K6*K30)+(L6*L30)+(M6*M30)+(N6*N30)+(O6*O30)+(P6*P30)+(Q6*Q30)+(R6*R30)+(S6*S30)+(T6*T30)+(U6*U30)+(V6*V30)+0+0+(W6*W30)+(X6*X30)+(Y30*Y6) -> 0
A31: ON SIGNERS
A32: 1 | Z32: =(D6*D32)+(E6*E32)+(F6*F32)+(G6*G32)+(H6*H32)+(I6*I32)+(J6*J32)+(K6*K32)+(L6*L32)+(M6*M32)+(N6*N32)+(O6*O32)+(P6*P32)+(Q6*Q32)+(R6*R32)+(S6*S32)+(T6*T32)+(U6*U32)+(V6*V32)+(W6*W32)+(X6*X32)+(Y6*Y32) -> 0
A33: 2 | Z33: =(D6*D33)+(E6*E33)+(F6*F33)+(G6*G33)+(H6*H33)+(I6*I33)+(J6*J33)+(K6*K33)+(L6*L33)+(M6*M33)+(N6*N33)+(O6*O33)+(P6*P33)+(Q6*Q33)+(R6*R33)+(S6*S33)+(T6*T33)+(U6*U33)+(V6*V33)+(W6*W33)+(X6*X33)+(Y6*Y33) -> 0
B34: Total: | D34: =SUM(D7:D33) -> 0 | E34: =SUM(E7:E33) -> 1 | F34: =SUM(F7:F33) -> 0 | G34: =SUM(G7:G33) -> 0 | O34: =SUM(O7:O33) -> 0 | P34: =SUM(P7:P33) -> 0 | Q34: =SUM(Q7:Q33) -> 0 | R34: =SUM(R7:R33) -> 0 | S34: =SUM(S7:S33) -> 0 | T34: =SUM(T7:T33) -> 0 | U34: =SUM(U7:U33) -> 0 | V34: =SUM(V7:V33) -> 0 | ... Y34: =SUM(Y7:Y33) -> 1
Z35: =SUM(Z7:Z34) -> 10.64
G40: Master Name
G41: Vessel

Sheet 19
A1: Wages account
H2: No.: 19
A3: Of: | B3: =#REF! -> #REF!
A4: Rank: | B4: =#REF! -> #REF!
A5: Wages Commence on the: | D5: =#REF! -> #REF!
A6: Paid until: | D6: =#REF! -> #REF!
A7: Total Monthly Wages: | D7: =#REF! -> #REF!
A8: Months: | B8: =#REF! -> #REF! | C8: Days: | D8: =#REF! -> #REF!
A9: Victualing Days:
H10: USD
A11: Total Basic Wages | C11: usd | D11: =#REF! -> #REF! | E11: =B8 -> #REF! | F11: m d | G11: =D8 -> #REF! | H11: =D11*G11/30 -> #REF!
A12: Fixed O/T | C12: usd | D12: =#REF! -> #REF! | E12: =B8 -> #REF! | F12: m d | G12: =D8 -> #REF! | H12: =D12*G12/30 -> #REF!
A13: Excess O/T | C13: hrs | E13: Rate | H13: =D13*F13 -> 0
A14: Extra 1 | C14: usd | D14: =#REF! -> #REF! | H14: =#REF! -> #REF!
A15: Extra 2 | C15: usd | H15: =D15/30*G15 -> 0
A16: Leave Pay | C16: usd | D16: =#REF! -> #REF! | E16: =B8 -> #REF! | F16: m d | G16: =D8 -> #REF! | H16: =D16*G16/30 -> #REF!
A17: Other Payments | C17: usd | D17: =#REF! -> #REF! | E17: =B8 -> #REF! | F17: m d | G17: =D9 -> 0 | H17: =D17*D8/30 -> #REF!
A18: Company Bonus | C18: usd | D18: =#REF! -> #REF! | E18: =B8 -> #REF! | F18: m d | G18: =D8 -> #REF! | H18: =D18*G18/30 -> #REF!
A19: Subsistence Allowance | D19: =#REF! -> #REF! | E19: =B8 -> #REF! | F19: m d | G19: =D8 -> #REF! | H19: =D19*G19/30 -> #REF!
A20: Total earningh of period | H20: =SUM(H11:H19) -> #REF!
A21: Credit / Debet from previous accounts | F21: =IF(H21<0,"Debit","Credit") -> Credit
A22: Total earning | H22: =H20+H21 -> #REF!
A24: Deductions | G24: USD
A25: S.S.S. | C25: usd | D25: =B8 -> #REF! | E25: m d | G25: =C25*D25+C25*F25/30 -> #REF!
A26: Allotment 1 | C26: usd | D26: =#REF! -> #REF! | G26: =#REF! -> #REF!
A27: Allotment 2 | D27: ='2AL'!D7 -> 0 | G27: ='2AL'!E25 -> 0
A28: Cigarettes & Spirits | D28: =IF(Slopchest!#REF!=0,"",Slopchest!#REF!) -> #REF! | E28: =IF(Slopchest!D7=0,"",Slopchest!$D$5) | F28: =IF(Slopchest!D7=0,"",Slopchest!D7) | G28: =Slopchest!Z25 -> 0
A29: Cables | G29: =#REF! -> #REF!
A30: Advance 1 | D30: ='1AD'!D7 -> #REF! | G30: ='1AD'!E25 -> 0
A31: Advance 2 | D31: =#REF! -> #REF! | G31: =#REF! -> #REF!
A32: Advance 3 | D32: ='3AD'!D7 -> #REF! | G32: ='3AD'!E25 -> 0
A33: Paid by Owners or Agents | G33: 0
A34: Other Deductions | C34: Fixed deduction | G34: =IF(#REF!=30,#REF!,#REF!/30*#REF!) -> #REF!
A35: Total deductions | G35: =SUM(G25:G34) -> #REF! | H35: =H22-G35 -> #REF!
A37: Credit / Debet balance | F37: =IF(H37<0,"Debet","Credit") -> #REF! | G37: USD | H37: =IF(H35=0,"NIL",H35) -> #REF!
A39: Balance to be remitted to Bank's account respectively
A40: Place: | F40: Date: | G40: =#REF! -> #REF!
A43: Master: | E43: Recipient:
B44: =#REF! -> #REF! | G44: =B3 -> #REF!

Sheet 20
A1: Wages account
H2: No.: 20
A3: Of: | B3: =#REF! -> #REF!
A4: Rank: | B4: =#REF! -> #REF!
A5: Wages Commence on the: | D5: =#REF! -> #REF!
A6: Paid until: | D6: =#REF! -> #REF!
A7: Total Monthly Wages: | D7: =#REF! -> #REF!
A8: Months: | B8: =#REF! -> #REF! | C8: Days: | D8: =#REF! -> #REF!
A9: Victualing Days:
H10: USD
A11: Total Basic Wages | C11: usd | D11: =#REF! -> #REF! | E11: =B8 -> #REF! | F11: m d | G11: =D8 -> #REF! | H11: =D11*G11/30 -> #REF!
A12: Fixed O/T | C12: usd | D12: =#REF! -> #REF! | E12: =B8 -> #REF! | F12: m d | G12: =D8 -> #REF! | H12: =D12*G12/30 -> #REF!
A13: Excess O/T | C13: hrs | E13: Rate | H13: =D13*F13 -> 0
A14: Extra 1 | C14: usd | D14: =#REF! -> #REF! | H14: =#REF! -> #REF!
A15: Extra 2 | C15: usd | H15: =D15/30*G15 -> 0
A16: Leave Pay | C16: usd | D16: =#REF! -> #REF! | E16: =B8 -> #REF! | F16: m d | G16: =D8 -> #REF! | H16: =D16*G16/30 -> #REF!
A17: Other Payments | C17: usd | D17: =#REF! -> #REF! | E17: =B8 -> #REF! | F17: m d | G17: =D9 -> 0 | H17: =D17*D8/30 -> #REF!
A18: Company Bonus | C18: usd | D18: =#REF! -> #REF! | E18: =B8 -> #REF! | F18: m d | G18: =D8 -> #REF! | H18: =D18*G18/30 -> #REF!
A19: Subsistence Allowance | D19: =#REF! -> #REF! | E19: =B8 -> #REF! | F19: m d | G19: =D8 -> #REF! | H19: =D19*G19/30 -> #REF!
A20: Total earningh of period | H20: =SUM(H11:H19) -> #REF!
A21: Credit / Debet from previous accounts | F21: =IF(H21<0,"Debit","Credit") -> Credit
A22: Total earning | H22: =H20+H21 -> #REF!
A24: Deductions | G24: USD
A25: S.S.S. | C25: usd | D25: =B8 -> #REF! | E25: m d | G25: =C25*D25+C25*F25/30 -> #REF!
A26: Allotment 1 | C26: usd | D26: =#REF! -> #REF! | G26: =#REF! -> #REF!
A27: Allotment 2 | D27: ='2AL'!D7 -> 0 | G27: ='2AL'!E26 -> 0
A28: Cigarettes & Spirits | D28: =IF(Slopchest!#REF!=0,"",Slopchest!#REF!) -> #REF! | E28: =IF(Slopchest!D7=0,"",Slopchest!$D$5) | F28: =IF(Slopchest!D7=0,"",Slopchest!D7) | G28: =Slopchest!#REF! -> #REF!
A29: Cables | G29: =#REF! -> #REF!
A30: Advance 1 | D30: ='1AD'!D7 -> #REF! | G30: ='1AD'!E26 -> 0
A31: Advance 2 | D31: =#REF! -> #REF! | G31: =#REF! -> #REF!
A32: Advance 3 | D32: ='3AD'!D7 -> #REF! | G32: ='3AD'!E26 -> 0
A33: Paid by Owners or Agents | G33: 0
A34: Other Deductions | C34: Fixed deduction | G34: =IF(#REF!=30,#REF!,#REF!/30*#REF!) -> #REF!
A35: Total deductions | G35: =SUM(G25:G34) -> #REF! | H35: =H22-G35 -> #REF!
A37: Credit / Debet balance | F37: =IF(H37<0,"Debet","Credit") -> #REF! | G37: USD | H37: =IF(H35=0,"NIL",H35) -> #REF!
A39: Balance to be remitted to Bank's account respectively
A40: Place: | F40: Date: | G40: =#REF! -> #REF!
A43: Master: | E43: Recipient:
B44: =#REF! -> #REF! | G44: =B3 -> #REF!

Sheet 21
A1: =#REF! -> #REF! | H1: AC
A3: =#REF! -> #REF!
C4: WAGES ACCOUNT
H5: No.: 20
A6: Of: | B6: =#REF! -> #REF!
A7: Rank : | B7: =#REF! -> #REF!
A8: Wages Commence on the:
A9: Paid until :
A10: Total Monthly Wages :
A11: Months : | C11: Days:
A12: Victualing Days :
H13: USD
A14: Total Basic Wages | C14: usd | E14: =B11 -> 0 | F14: m d | G14: =D11 | H14: =CEILING(D14*E14+D14*G14/30,0.01) -> 0
A15: Fixed O/T | C15: usd | E15: =B11 -> 0 | F15: m d | G15: =D11 | H15: =CEILING(D15*E15+D15*G15/30,0.01) -> 0
A16: Excess O/T | C16: hrs: | E16: Rate : | H16: =CEILING(D16*F16,0.01) -> 0
A17: Extra 1
A18: Extra 2
A19: Leave Pay | C19: usd | E19: =B11 -> 0 | F19: m d | G19: =D11 | H19: =CEILING(D19*E19+D19*G19/30,0.01) -> 0
A20: Other Payments
A21: Company Bonus | C21: usd | E21: =B11 -> 0 | F21: m d | G21: =D11 | H21: =D21*E21+D21*G21/30 -> 0
A22: Master's Bonus
A23: TOTAL EARNINGS OF PERIOD | H23: =SUM(H14:H22) -> 0
A24: CREDIT/DEBIT FM PREVIOUS ACCOUNTS | F24: =IF(H24<0,"DEBIT","CREDIT") -> CREDIT
A25: TOTAL EARNINGS | H25: =H23+H24 -> 0
A27: DEDUCTIONS | G27: USD
A28: S.S.S. | B28: usd | D28: =B11 -> 0 | E28: m d | F28: =D11 | G28: =C28*D28+C28*F28/30 -> 0
A29: Allotment 1 | D29: =#REF! -> #REF! | G29: =#REF! -> #REF!
A30: Allotment 2 | D30: ='2AL'!D26 -> 0 | G30: ='2AL'!E26 -> 0
A31: Allotment 3 | D31: =#REF! -> #REF! | G31: =#REF! -> #REF!
A32: Cigarettes & Spirits | C32: =#REF! -> #REF! | G32: =#REF! -> #REF!
A33: Cables | D33: =#REF! -> #REF! | G33: =#REF! -> #REF!
A34: Advance 1 | D34: ='1AD'!D26 -> 0 | G34: ='1AD'!E26 -> 0
A35: Advance 2 | D35: =#REF! -> #REF! | G35: =#REF! -> #REF!
A36: Advance 3 | D36: ='3AD'!D26 -> 0 | G36: ='3AD'!E26 -> 0
A37: Paid by Owners or Agents
A38: Other Deductions
A39: TOTAL DEDUCTIONS | G39: =SUM(G28:G38) -> #REF!
A41: CREDIT / DEBIT BALANCE | F41: =IF(H41<0,"DEBIT","CREDIT") -> #REF! | G41: USD | H41: =H25-G39 -> #REF!
A43: I received my wages up to date in full settlement including overtimes, leave allowance etc., and have no further claim whatsoever against the Vessel, her Owners, Master and/or any Agents thereof.
A44: Place: | E44: Date:
...

Sheet Foglio2

Sheet Foglio3

Sheet Foglio4
