Workbook

Sheet 2AL
A4: ALLOTMENT 2
A6: No | B6: Name | C6: Rank | D6: Month / Year | E6: Amount USD
A7: 1 | B7: =#REF! -> #REF! | C7: =#REF! -> #REF!
A8: 2 | B8: =#REF! -> #REF! | C8: =#REF! -> #REF!
A9: 3 | B9: =#REF! -> #REF! | C9: =#REF! -> #REF!
A10: 4 | B10: =#REF! -> #REF! | C10: =#REF! -> #REF!
A11: 5 | B11: =#REF! -> #REF! | C11: =#REF! -> #REF!
A12: 6 | B12: =#REF! -> #REF! | C12: =#REF! -> #REF!
A13: 7 | B13: =#REF! -> #REF! | C13: =#REF! -> #REF!
A14: 8 | B14: =#REF! -> #REF! | C14: =#REF! -> #REF!
A15: 9 | B15: =#REF! -> #REF! | C15: =#REF! -> #REF!
A16: 10 | B16: =#REF! -> #REF! | C16: =#REF! -> #REF!
A17: 11 | B17: =#REF! -> #REF! | C17: =#REF! -> #REF!
A18: 12 | B18: =#REF! -> #REF! | C18: =#REF! -> #REF!
A19: 13 | B19: =#REF! -> #REF! | C19: =#REF! -> #REF!
... A26: 20 | B26: =#REF! -> #REF! | C26: =#REF! -> #REF!
A27: 31
D28: Total USD | E28: =SUM(E7:E27) -> 0
C33: Master | D33: =#REF! -> #REF!

Sheet 1AD
E2: =#REF! -> #REF!
A4: CASH ADVANCE 1
A6: No | B6: Name | C6: Rank | D6: Month / Year | E6: Amount USD
A7: 1 | B7: =#REF! -> #REF! | C7: =#REF! -> #REF! | D7: =#REF! -> #REF!
A8: 2 | B8: =#REF! -> #REF! | C8: =#REF! -> #REF! | D8: =#REF! -> #REF!
A9: 3 | B9: =#REF! -> #REF! | C9: =#REF! -> #REF! | D9: =#REF! -> #REF!
A10: 4 | B10: =#REF! -> #REF! | C10: =#REF! -> #REF! | D10: =#REF! -> #REF!
A11: 5 | B11: =#REF! -> #REF! | C11: =#REF! -> #REF! | D11: =#REF! -> #REF!
A12: 6 | B12: =#REF! -> #REF! | C12: =#REF! -> #REF! | D12: =#REF! -> #REF!
A13: 7 | B13: =#REF! -> #REF! | C13: =#REF! -> #REF! | D13: =#REF! -> #REF!
A14: 8 | B14: =#REF! -> #REF! | C14: =#REF! -> #REF! | D14: =#REF! -> #REF!
A15: 9 | B15: =#REF! -> #REF! | C15: =#REF! -> #REF! | D15: =#REF! -> #REF!
A16: 10 | B16: =#REF! -> #REF! | C16: =#REF! -> #REF! | D16: =#REF! -> #REF!
A17: 11 | B17: =#REF! -> #REF! | C17: =#REF! -> #REF! | D17: =#REF! -> #REF!
A18: 12 | B18: =#REF! -> #REF! | C18: =#REF! -> #REF! | D18: =#REF! -> #REF!
... A20: 14 | B20: =#REF! -> #REF! | C20: =#REF! -> #REF! | D20: =#REF! -> #REF!
A21: 15 | B21: =#REF! -> #REF! | C21: =#REF! -> #REF! | D21: =IF(B21="","",#REF!) -> #REF!
A22: 16 | B22: =#REF! -> #REF! | C22: =#REF! -> #REF! | D22: =IF(B22="","",#REF!) -> #REF!
A23: 17 | B23: =#REF! -> #REF! | C23: =#REF! -> #REF! | D23: =IF(B23="","",#REF!) -> #REF!
A24: 18 | B24: =#REF! -> #REF! | C24: =#REF! -> #REF! | D24: =IF(B24="","",#REF!) -> #REF!
A25: 19 | B25: =#REF! -> #REF! | C25: =#REF! -> #REF! | D25: =IF(B25="","",#REF!) -> #REF!
A26: 20 | B26: =#REF! -> #REF! | C26: =#REF! -> #REF!
D27: Total USD | E27: =SUM(E7:E26) -> 0
C32: =#REF! -> #REF!
C34: Master | D34: =#REF! -> #REF!

Sheet 3AD
A4: CASH ADVANCE 3
A6: No | B6: Name | C6: Rank | D6: Month / Year | E6: Amount USD
A7: =#REF! -> #REF! | B7: =#REF! -> #REF! | C7: =#REF! -> #REF! | D7: =IF(B7="","",#REF!) -> #REF! | J7: =I7*$I$6 -> 0
A8: =#REF! -> #REF! | B8: =#REF! -> #REF! | C8: =#REF! -> #REF! | D8: =IF(B8="","",#REF!) -> #REF! | J8: =I8*$I$6 -> 0
A9: =#REF! -> #REF! | B9: =#REF! -> #REF! | C9: =#REF! -> #REF! | D9: =IF(B9="","",#REF!) -> #REF! | J9: =I9*$I$6 -> 0 | L9: =K9*$K$6 -> 0
A10: =#REF! -> #REF! | B10: =#REF! -> #REF! | C10: =#REF! -> #REF! | D10: =IF(B10="","",#REF!) -> #REF! | J10: =I10*$I$6 -> 0 | L10: =K10*$K$6 -> 0
A11: =#REF! -> #REF! | B11: =#REF! -> #REF! | C11: =#REF! -> #REF! | D11: =IF(B11="","",#REF!) -> #REF! | J11: =I11*$I$6 -> 0 | L11: =K11*$K$6 -> 0
A12: =#REF! -> #REF! | B12: =#REF! -> #REF! | C12: =#REF! -> #REF! | D12: =IF(B12="","",#REF!) -> #REF! | J12: =I12*$I$6 -> 0 | L12: =K12*$K$6 -> 0
A13: =#REF! -> #REF! | B13: =#REF! -> #REF! | C13: =#REF! -> #REF! | D13: =IF(B13="","",#REF!) -> #REF! | J13: =I13*$I$6 -> 0 | L13: =K13*$K$6 -> 0
A14: =#REF! -> #REF! | B14: =#REF! -> #REF! | C14: =#REF! -> #REF! | D14: =IF(B14="","",#REF!) -> #REF! | J14: =I14*$I$6 -> 0 | L14: =K14*$K$6 -> 0
A15: =#REF! -> #REF! | B15: =#REF! -> #REF! | C15: =#REF! -> #REF! | D15: =IF(B15="","",#REF!) -> #REF! | J15: =I15*$I$6 -> 0 | L15: =K15*$K$6 -> 0
A16: =#REF! -> #REF! | B16: =#REF! -> #REF! | C16: =#REF! -> #REF! | D16: =IF(B16="","",#REF!) -> #REF! | J16: =I16*$I$6 -> 0 | L16: =K16*$K$6 -> 0
A17: =#REF! -> #REF! | B17: =#REF! -> #REF! | C17: =#REF! -> #REF! | D17: =IF(B17="","",#REF!) -> #REF! | J17: =I17*$I$6 -> 0 | L17: =K17*$K$6 -> 0
A18: =#REF! -> #REF! | B18: =#REF! -> #REF! | C18: =#REF! -> #REF! | D18: =IF(B18="","",#REF!) -> #REF! | J18: =I18*$I$6 -> 0 | L18: =K18*$K$6 -> 0
A19: =#REF! -> #REF! | B19: =#REF! -> #REF! | C19: =#REF! -> #REF! | D19: =IF(B19="","",#REF!) -> #REF! | J19: =I19*$I$6 -> 0 | L19: =K19*$K$6 -> 0
A20: =#REF! -> #REF! | B20: =#REF! -> #REF! | C20: =#REF! -> #REF! | D20: =IF(B20="","",#REF!) -> #REF! | J20: =I20*$I$6 -> 0 | L20: =K20*$K$6 -> 0
A21: 15 | B21: =#REF! -> #REF! | C21: =#REF! -> #REF! | D21: =IF(B21="","",#REF!) -> #REF! | J21: =I21*$I$6 -> 0 | L21: =K21*$K$6 -> 0
A22: =#REF! -> #REF! | B22: =#REF! -> #REF! | C22: =#REF! -> #REF! | D22: =IF(B22="","",#REF!) -> #REF! | J22: =I22*$I$6 -> 0 | L22: =K22*$K$6 -> 0
A23: 17 | B23: =#REF! -> #REF! | C23: =#REF! -> #REF! | D23: =IF(B23="","",#REF!) -> #REF! | L23: =K23*$K$6 -> 0
A24: =#REF! -> #REF! | B24: =#REF! -> #REF! | C24: =#REF! -> #REF! | D24: =IF(B24="","",#REF!) -> #REF! | L24: =K24*$K$6 -> 0
A25: =#REF! -> #REF! | B25: =#REF! -> #REF! | C25: =#REF! -> #REF! | D25: =IF(B25="","",#REF!) -> #REF! | L25: =K25*$K$6 -> 0
A26: =#REF! -> #REF! | B26: =#REF! -> #REF! | C26: =#REF! -> #REF!
D27: Total USD | E27: =SUM(E7:E26) -> 0
C34: Master | D34: =#REF! -> #REF!

Sheet Bond
A1: BOND CONSUMPTION (OWNERS ACCOUNT)
A3: Vessel: | C3: "XXXX" | H3: Date: | I3: 46022
A5: No. | B5: Items | D5: Units | E5: Representation | F5: Qty Consumed | G5: Price USD | H5: Total Received | I5: Total Price USD
A6: 1 | B6: Marlboro Gold Cigarattes / old | E6: Customs, Immigrations, Agent, Harbour Master(TANJUNG BERAKIT) | F6: 4 | G6: 25.56 | I6: =F6*G6 -> 102.24
A7: 2 | B7: Manchester Light Cigarattes / New | E7: Customs, Immigrations, Agent, Harbour Master(TANJUNG BERAKIT) | F7: 5 | G7: 6.92 | I7: =F7*G7 -> 34.6
A8: 3 | B8: Manchester Light Cigarattes / New | E8: 2 SayBolt Surveyors & 1 Sampling Person(TANJUNG BERAKIT) | F8: 3 | G8: 6.92 | I8: =F8*G8 -> 20.76
A9: 4 | B9: Coke | E9: Customs, Immigrations, Agent, Harbour Master(TANJUNG BERAKIT) | F9: 1 | G9: 13.62 | I9: =F9*G9 -> 13.62
A10: 5 | B10: Chocolate Snickers (45 G) | E10: Customs, Immigrations, Agent, Harbour Master(TANJUNG BERAKIT) | F10: 2 | G10: 1.3 | I10: =F10*G10 -> 2.6
A11: 6 | B11: Manchester Light Cigarattes / New | E11: Agent,Immigrations,Loading Master,Terminal Manager,Surveyors(YANGPU) | F11: 13 | G11: 6.92 | I11: =F11*G11 -> 89.96
A12: 7 | B12: Marlboro Gold Cigarattes / old | E12: ARRIVAL/DEPARTURE PILOTS (YANGPU) | F12: 5 | G12: 25.56 | I12: =F12*G12 -> 127.8
A13: 8 | B13: Coke | E13: Agent,Immigrations,Loading Master,Terminal Manager,Surveyors(YANGPU) | F13: 1 | G13: 13.62 | I13: =F13*G13 -> 13.62
A14: 9 | B14: Drinking Water 500ml | E14: Agent,Immigrations,Loading Master,Terminal Manager,Surveyors,Pilots(YANGPU) | F14: 1 | G14: 3.359 | I14: =F14*G14 -> 3.359
A15: Total Expenses: | I15: =SUM(I6:I14) -> 408.559
H25: Master Name
H26: Vessel Name

Sheet 19
A1: Wages account
H2: No.: 19
A3: Of: | B3: =#REF! -> #REF!
A4: Rank: | B4: =#REF! -> #REF!
A5: Wages Commence on the: | D5: =#REF! -> #REF!
A6: Paid until: | D6: =#REF! -> #REF!
A7: Total Monthly Wages: | D7: =#REF! -> #REF!
A8: Months: | B8: =#REF! -> #REF! | C8: Days: | D8: =#REF! -> #REF!
A9: Victualing Days:
H10: USD
A11: Total Basic Wages | C11: usd | D11: =#REF! -> #REF! | E11: =B8 -> #REF! | F11: m d | G11: =D8 -> #REF! | H11: =D11*G11/30 -> #REF!
A12: Fixed O/T | C12: usd | D12: =#REF! -> #REF! | E12: =B8 -> #REF! | F12: m d | G12: =D8 -> #REF! | H12: =D12*G12/30 -> #REF!
A13: Excess O/T | C13: hrs | E13: Rate | H13: =D13*F13 -> 0
A14: Extra 1 | C14: usd | D14: =#REF! -> #REF! | H14: =#REF! -> #REF!
A15: Extra 2 | C15: usd | H15: =D15/30*G15 -> 0
A16: Leave Pay | C16: usd | D16: =#REF! -> #REF! | E16: =B8 -> #REF! | F16: m d | G16: =D8 -> #REF! | H16: =D16*G16/30 -> #REF!
A17: Other Payments | C17: usd | D17: =#REF! -> #REF! | E17: =B8 -> #REF! | F17: m d | G17: =D9 -> 0 | H17: =D17*D8/30 -> #REF!
A18: Company Bonus | C18: usd | D18: =#REF! -> #REF! | E18: =B8 -> #REF! | F18: m d | G18: =D8 -> #REF! | H18: =D18*G18/30 -> #REF!
A19: Subsistence Allowance | D19: =#REF! -> #REF! | E19: =B8 -> #REF! | F19: m d | G19: =D8 -> #REF! | H19: =D19*G19/30 -> #REF!
A20: Total earningh of period | H20: =SUM(H11:H19) -> #REF!
A21: Credit / Debet from previous accounts | F21: =IF(H21<0,"Debit","Credit") -> Credit
A22: Total earning | H22: =H20+H21 -> #REF!
A24: Deductions | G24: USD
A25: S.S.S. | C25: usd | D25: =B8 -> #REF! | E25: m d | G25: =C25*D25+C25*F25/30 -> #REF!
A26: Allotment 1 | C26: usd | D26: =#REF! -> #REF! | G26: =#REF! -> #REF!
A27: Allotment 2 | D27: ='2AL'!D7 -> 0 | G27: ='2AL'!E25 -> 0
A28: Cigarettes & Spirits | D28: =IF(#REF!=0,"",#REF!) -> #REF! | E28: =IF(#REF!=0,"",#REF!) -> #REF! | F28: =IF(#REF!=0,"",#REF!) -> #REF! | G28: =#REF! -> #REF!
A29: Cables | G29: =#REF! -> #REF!
A30: Advance 1 | D30: ='1AD'!D7 -> #REF! | G30: ='1AD'!E25 -> 0
A31: Advance 2 | D31: =#REF! -> #REF! | G31: =#REF! -> #REF!
A32: Advance 3 | D32: ='3AD'!D7 -> #REF! | G32: ='3AD'!E25 -> 0
A33: Paid by Owners or Agents | G33: 0
A34: Other Deductions | C34: Fixed deduction | G34: =IF(#REF!=30,#REF!,#REF!/30*#REF!) -> #REF!
A35: Total deductions | G35: =SUM(G25:G34) -> #REF! | H35: =H22-G35 -> #REF!
A37: Credit / Debet balance | F37: =IF(H37<0,"Debet","Credit") -> #REF! | G37: USD | H37: =IF(H35=0,"NIL",H35) -> #REF!
A39: Balance to be remitted to Bank's account respectively
A40: Place: | F40: Date: | G40: =#REF! -> #REF!
A43: Master: | E43: Recipient:
B44: =#REF! -> #REF! | G44: =B3 -> #REF!

Sheet 20
A1: Wages account
H2: No.: 20
A3: Of: | B3: =#REF! -> #REF!
A4: Rank: | B4: =#REF! -> #REF!
A5: Wages Commence on the: | D5: =#REF! -> #REF!
A6: Paid until: | D6: =#REF! -> #REF!
A7: Total Monthly Wages: | D7: =#REF! -> #REF!
A8: Months: | B8: =#REF! -> #REF! | C8: Days: | D8: =#REF! -> #REF!
A9: Victualing Days:
H10: USD
A11: Total Basic Wages | C11: usd | D11: =#REF! -> #REF! | E11: =B8 -> #REF! | F11: m d | G11: =D8 -> #REF! | H11: =D11*G11/30 -> #REF!
A12: Fixed O/T | C12: usd | D12: =#REF! -> #REF! | E12: =B8 -> #REF! | F12: m d | G12: =D8 -> #REF! | H12: =D12*G12/30 -> #REF!
A13: Excess O/T | C13: hrs | E13: Rate | H13: =D13*F13 -> 0
A14: Extra 1 | C14: usd | D14: =#REF! -> #REF! | H14: =#REF! -> #REF!
A15: Extra 2 | C15: usd | H15: =D15/30*G15 -> 0
A16: Leave Pay | C16: usd | D16: =#REF! -> #REF! | E16: =B8 -> #REF! | F16: m d | G16: =D8 -> #REF! | H16: =D16*G16/30 -> #REF!
A17: Other Payments | C17: usd | D17: =#REF! -> #REF! | E17: =B8 -> #REF! | F17: m d | G17: =D9 -> 0 | H17: =D17*D8/30 -> #REF!
A18: Company Bonus | C18: usd | D18: =#REF! -> #REF! | E18: =B8 -> #REF! | F18: m d | G18: =D8 -> #REF! | H18: =D18*G18/30 -> #REF!
A19: Subsistence Allowance | D19: =#REF! -> #REF! | E19: =B8 -> #REF! | F19: m d | G19: =D8 -> #REF! | H19: =D19*G19/30 -> #REF!
A20: Total earningh of period | H20: =SUM(H11:H19) -> #REF!
A21: Credit / Debet from previous accounts | F21: =IF(H21<0,"Debit","Credit") -> Credit
A22: Total earning | H22: =H20+H21 -> #REF!
A24: Deductions | G24: USD
A25: S.S.S. | C25: usd | D25: =B8 -> #REF! | E25: m d | G25: =C25*D25+C25*F25/30 -> #REF!
A26: Allotment 1 | C26: usd | D26: =#REF! -> #REF! | G26: =#REF! -> #REF!
A27: Allotment 2 | D27: ='2AL'!D7 -> 0 | G27: ='2AL'!E26 -> 0
A28: Cigarettes & Spirits | D28: =IF(#REF!=0,"",#REF!) -> #REF! | E28: =IF(#REF!=0,"",#REF!) -> #REF! | F28: =IF(#REF!=0,"",#REF!) -> #REF! | G28: =#REF! -> #REF!
A29: Cables | G29: =#REF! -> #REF!
A30: Advance 1 | D30: ='1AD'!D7 -> #REF! | G30: ='1AD'!E26 -> 0
A31: Advance 2 | D31: =#REF! -> #REF! | G31: =#REF! -> #REF!
A32: Advance 3 | D32: ='3AD'!D7 -> #REF! | G32: ='3AD'!E26 -> 0
A33: Paid by Owners or Agents | G33: 0
A34: Other Deductions | C34: Fixed deduction | G34: =IF(#REF!=30,#REF!,#REF!/30*#REF!) -> #REF!
A35: Total deductions | G35: =SUM(G25:G34) -> #REF! | H35: =H22-G35 -> #REF!
A37: Credit / Debet balance | F37: =IF(H37<0,"Debet","Credit") -> #REF! | G37: USD | H37: =IF(H35=0,"NIL",H35) -> #REF!
A39: Balance to be remitted to Bank's account respectively
A40: Place: | F40: Date: | G40: =#REF! -> #REF!
A43: Master: | E43: Recipient:
B44: =#REF! -> #REF! | G44: =B3 -> #REF!

Sheet 21
A1: =#REF! -> #REF! | H1: AC
A3: =#REF! -> #REF!
C4: WAGES ACCOUNT
H5: No.: 20
A6: Of: | B6: =#REF! -> #REF!
A7: Rank : | B7: =#REF! -> #REF!
A8: Wages Commence on the:
A9: Paid until :
A10: Total Monthly Wages :
A11: Months : | C11: Days:
A12: Victualing Days :
H13: USD
A14: Total Basic Wages | C14: usd | E14: =B11 -> 0 | F14: m d | G14: =D11 | H14: =CEILING(D14*E14+D14*G14/30,0.01) -> 0
A15: Fixed O/T | C15: usd | E15: =B11 -> 0 | F15: m d | G15: =D11 | H15: =CEILING(D15*E15+D15*G15/30,0.01) -> 0
A16: Excess O/T | C16: hrs: | E16: Rate : | H16: =CEILING(D16*F16,0.01) -> 0
A17: Extra 1
A18: Extra 2
A19: Leave Pay | C19: usd | E19: =B11 -> 0 | F19: m d | G19: =D11 | H19: =CEILING(D19*E19+D19*G19/30,0.01) -> 0
A20: Other Payments
A21: Company Bonus | C21: usd | E21: =B11 -> 0 | F21: m d | G21: =D11 | H21: =D21*E21+D21*G21/30 -> 0
A22: Master's Bonus
A23: TOTAL EARNINGS OF PERIOD | H23: =SUM(H14:H22) -> 0
A24: CREDIT/DEBIT FM PREVIOUS ACCOUNTS | F24: =IF(H24<0,"DEBIT","CREDIT") -> CREDIT
A25: TOTAL EARNINGS | H25: =H23+H24 -> 0
A27: DEDUCTIONS | G27: USD
A28: S.S.S. | B28: usd | D28: =B11 -> 0 | E28: m d | F28: =D11 | G28: =C28*D28+C28*F28/30 -> 0
A29: Allotment 1 | D29: =#REF! -> #REF! | G29: =#REF! -> #REF!
A30: Allotment 2 | D30: ='2AL'!D26 -> 0 | G30: ='2AL'!E26 -> 0
A31: Allotment 3 | D31: =#REF! -> #REF! | G31: =#REF! -> #REF!
A32: Cigarettes & Spirits | C32: =#REF! -> #REF! | G32: =#REF! -> #REF!
A33: Cables | D33: =#REF! -> #REF! | G33: =#REF! -> #REF!
A34: Advance 1 | D34: ='1AD'!D26 -> 0 | G34: ='1AD'!E26 -> 0
A35: Advance 2 | D35: =#REF! -> #REF! | G35: =#REF! -> #REF!
A36: Advance 3 | D36: ='3AD'!D26 -> 0 | G36: ='3AD'!E26 -> 0
A37: Paid by Owners or Agents
A38: Other Deductions
A39: TOTAL DEDUCTIONS | G39: =SUM(G28:G38) -> #REF!
A41: CREDIT / DEBIT BALANCE | F41: =IF(H41<0,"DEBIT","CREDIT") -> #REF! | G41: USD | H41: =H25-G39 -> #REF!
A43: I received my wages up to date in full settlement including overtimes, leave allowance etc., and have no further claim whatsoever against the Vessel, her Owners, Master and/or any Agents thereof.
A44: Place: | E44: Date:
...

Sheet Foglio2

Sheet Foglio3

Sheet Foglio4
